Workbook

Sheet README
A1: Kế hoạch quản lý dự án: Phần mềm Quản lý Thư viện Trường Đại học (Đề tài 8)
A2: Dự án mô phỏng 16 tuần, 4 người. Mọi bảng tính đều dùng công thức; ô vàng là dữ liệu nhập, ô xám là kết quả tính.
A4: Sheet | B4: Nội dung
A5: GiaDinh | B5: Tham số dùng chung: đơn giá, năng lực, dự phòng, hệ số 3 điểm, giả định tài chính và EVA.
A6: WBS | B6: WBS 3 cấp, ước lượng giờ công 3 điểm (PERT), chi phí kế hoạch (BAC).
A7: CPM | B7: Bảng hoạt động, phụ thuộc FS/SS, ES/EF/LS/LF, độ dự trữ, đường găng.
A8: PERT | B8: Ước lượng 3 điểm cho hoạt động và xác suất hoàn thành đúng hạn.
A9: Gantt | B9: Biểu đồ Gantt theo tuần; đỏ là hoạt động găng, xanh là hoạt động có độ dự trữ.
A10: NguonLuc | B10: Giờ kế hoạch theo tuần và theo vai trò (nền của PV), so với năng lực.
A11: RuiRo | B11: Sổ rủi ro: xác suất, tác động, điểm, EMV, ứng phó; ma trận 5x5.
A12: RACI | B12: Ma trận trách nhiệm RACI, kiểm tra mỗi gói có đúng một người chịu trách nhiệm cuối (A).
A13: TaiChinh | B13: Chi phí, lợi ích 3 năm, NPV, ROI, thời gian hoàn vốn, độ nhạy.
A14: EVA | B14: Phân tích giá trị thu được theo tuần: PV, EV, AC, SV, CV, SPI, CPI, EAC, ETC, VAC, TCPI.
A15: Timelog | B15: Giờ công thật ghi nhận của nhóm (từ docs/pm/timelog.csv).
A16: ChatLuong | B16: Mốc chất lượng và tiêu chí chấp nhận, kết quả kiểm thử thật.
A19: Quy ước màu
A20: Ô nhập (đổi được)
A21: Ô tính (không sửa tay)
A22: Hoạt động găng
A23: Hoạt động có dự trữ
A25: Lưu ý: EV và AC trong sheet EVA là số mô phỏng có kiểm soát (xem giả định ở sheet GiaDinh), không phải số đo của dự án thật.

Sheet GiaDinh
A1: Giả định và tham số dùng chung
A2: Đổi ô vàng thì toàn bộ WBS, PV, EVA và tài chính tự cập nhật.
A4: Tham số | B4: Giá trị | C4: Ghi chú
A5: Đơn giá giờ công (đ/giờ) | B5: 50000 | C5: Giả định sinh viên thực tập
A6: Số tuần dự án | B6: 16 | C6: 1 tuần thật = 2 tuần mô phỏng
A7: Năng lực mỗi người (giờ/tuần) | B7: 16 | C7: Bán thời gian, khoảng 2 ngày/tuần
A8: Số người | B8: 4 | C8: PM, Frontend và AI, Backend và DevOps, BA và QA
A9: Dự phòng quản lý (% BAC) | B9: 0.1 | C9: Dùng cho thay đổi được duyệt và rủi ro
A10: Tỉ lệ chiết khấu | B10: 0.1 | C10: Chi phí vốn giả định
A12: Hệ số ước lượng 3 điểm theo mức bất định | E12: Hệ số 3 điểm cho hoạt động (sheet PERT)
A13: Mức | B13: Lạc quan (O = M x) | C13: Bi quan (P = M x) | E13: Mức | F13: Lạc quan (a = m x) | G13: Bi quan (b = m x)
A14: L | B14: 0.85 | C14: 1.25 | E14: L | F14: 0.8 | G14: 1.3
A15: M | B15: 0.8 | C15: 1.4 | E15: M | F15: 0.75 | G15: 1.4
A16: H | B16: 0.7 | C16: 1.8 | E16: H | F16: 0.7 | G16: 1.6
A18: Giả định tài chính
A19: Tham số | B19: Giá trị | C19: Ghi chú
A20: Số bạn đọc (sinh viên, giảng viên) | B20: 5000 | C20: Giả định quy mô trường
A21: Lượt mượn mỗi bạn đọc mỗi năm | B21: 8
A22: Phút thủ thư tiết kiệm mỗi lượt mượn trả | B22: 2 | C22: Ghi sổ tay 3 phút, quét mã 1 phút
A23: Lượt tra cứu hộ mỗi năm | B23: 20000
A24: Phút tiết kiệm mỗi lượt tra cứu | B24: 2
A25: Đơn giá giờ thủ thư (đ/giờ) | B25: 35000
A26: Giờ làm báo cáo thống kê tiết kiệm mỗi năm | B26: 96 | C26: 12 báo cáo x 8 giờ
A27: Giá trị sách mất mỗi năm hiện nay (đ) | B27: 20000000
A28: Tỉ lệ giảm thất thoát nhờ theo dõi quá hạn | B28: 0.25
A29: Mức áp dụng năm 1 | B29: 0.7 | C29: 70% do làm quen
A30: Mức áp dụng năm 2 | B30: 1
A31: Mức áp dụng năm 3 | B31: 1
A32: Hạ tầng trả phí tối thiểu (đ/năm) | B32: 6000000 | C32: Phương án thay free-tier khi vận hành thật
A33: Giờ bảo trì mỗi năm | B33: 60
A34: Đào tạo, hỗ trợ mỗi năm (đ) | B34: 3000000
A37: Giả định EVA (số mô phỏng có kiểm soát)
A38: Giai đoạn | B38: Hiệu suất tiến độ (EV/PV trong tuần) | C38: Hệ số chi phí (giờ thực/giờ thu được) | D38: Lý do
A39: Tuần 1-4 | B39: 0.96 | C39: 1.04 | D39: Khảo sát và SRS cần làm rõ thêm nghiệp vụ gia hạn, phạt trả trễ, nên tiến độ chậm nhẹ.
A40: Tuần 5-8 | B40: 0.8 | C40: 1.12 | D40: Nhập dữ liệu Google Books bị giới hạn tần suất, phải chuyển sang bộ goodbooks-10k và dựng lại seed; chi phí sửa lỗi cao.
A41: Tuần 9-12 | B41: 1.1 | C41: 1.1 | D41: Làm thêm giờ và chạy song song Frontend với Backend để bù trễ; phát sinh sửa lỗi tính phạt theo ngày lịch.
A42: Tuần 13-16 | B42: 1.12 | C42: 1.05 | D42: Tích hợp, kiểm thử hệ thống và triển khai chạy nhanh nhờ khung CI/CD dựng sẵn; hoàn thành đúng hạn.

Sheet WBS
A1: WBS và ước lượng giờ công (PERT 3 điểm)
A2: E = (O + 4M + P) / 6; sigma = (P - O) / 6. O và P tính từ M theo mức bất định ở sheet GiaDinh.
A4: Mã WBS | B4: Gói công việc (Work Package) | C4: Pha | D4: Vai trò | E4: Hoạt động | F4: Mức | G4: M (giờ) | H4: O (giờ) | I4: P (giờ) | J4: E (giờ) | K4: Sigma | L4: Chi phí (đ) | M4: Sản phẩm bàn giao
A5: 1.1 | B5: Lập hiến chương dự án và SOW | C5: Khởi tạo | D5: PM | E5: A | F5: L | G5: 8 | H5: =ROUND(G5*VLOOKUP(F5,GiaDinh!$A$14:$C$16,2,FALSE),1) | I5: =ROUND(G5*VLOOKUP(F5,GiaDinh!$A$14:$C$16,3,FALSE),1) | J5: =(H5+4*G5+I5)/6 | K5: =(I5-H5)/6 | L5: =J5*GiaDinh!$B$5 | M5: Project Charter, SOW
A6: 1.2 | B6: Phân tích bên liên quan, kế hoạch truyền thông | C6: Khởi tạo | D6: PM | E6: A | F6: L | G6: 6 | H6: =ROUND(G6*VLOOKUP(F6,GiaDinh!$A$14:$C$16,2,FALSE),1) | I6: =ROUND(G6*VLOOKUP(F6,GiaDinh!$A$14:$C$16,3,FALSE),1) | J6: =(H6+4*G6+I6)/6 | K6: =(I6-H6)/6 | L6: =J6*GiaDinh!$B$5 | M6: Sổ bên liên quan
A7: 1.3 | B7: Dựng môi trường: repo, nhánh bảo vệ, Neon, khung 3 dịch vụ | C7: Khởi tạo | D7: BE | E7: B | F7: M | G7: 14 | H7: =ROUND(G7*VLOOKUP(F7,GiaDinh!$A$14:$C$16,2,FALSE),1) | I7: =ROUND(G7*VLOOKUP(F7,GiaDinh!$A$14:$C$16,3,FALSE),1) | J7: =(H7+4*G7+I7)/6 | K7: =(I7-H7)/6 | L7: =J7*GiaDinh!$B$5 | M7: Repo, CI khung, /health
A8: 2.1 | B8: Khảo sát nghiệp vụ thư viện, phỏng vấn thủ thư (giả định) | C8: Phân tích | D8: QA | E8: C | F8: M | G8: 12 | H8: =ROUND(G8*VLOOKUP(F8,GiaDinh!$A$14:$C$16,2,FALSE),1) | I8: =ROUND(G8*VLOOKUP(F8,GiaDinh!$A$14:$C$16,3,FALSE),1) | J8: =(H8+4*G8+I8)/6 | K8: =(I8-H8)/6 | L8: =J8*GiaDinh!$B$5 | M8: Biên bản khảo sát
A9: 2.2 | B9: Đặc tả SRS IEEE 830 và 20 User Story | C9: Phân tích | D9: QA | E9: D | F9: M | G9: 26 | H9: =ROUND(G9*VLOOKUP(F9,GiaDinh!$A$14:$C$16,2,FALSE),1) | I9: =ROUND(G9*VLOOKUP(F9,GiaDinh!$A$14:$C$16,3,FALSE),1) | J9: =(H9+4*G9+I9)/6 | K9: =(I9-H9)/6 | L9: =J9*GiaDinh!$B$5 | M9: SRS, backlog
A10: 2.3 | B10: Mô hình use case, quy tắc nghiệp vụ BR | C10: Phân tích | D10: QA | E10: D | F10: L | G10: 8 | H10: =ROUND(G10*VLOOKUP(F10,GiaDinh!$A$14:$C$16,2,FALSE),1) | I10: =ROUND(G10*VLOOKUP(F10,GiaDinh!$A$14:$C$16,3,FALSE),1) | J10: =(H10+4*G10+I10)/6 | K10: =(I10-H10)/6 | L10: =J10*GiaDinh!$B$5 | M10: Use case, BR-01..BR-08
A11: 3.1 | B11: Thiết kế kiến trúc 3 dịch vụ và gateway | C11: Thiết kế | D11: PM | E11: E | F11: L | G11: 10 | H11: =ROUND(G11*VLOOKUP(F11,GiaDinh!$A$14:$C$16,2,FALSE),1) | I11: =ROUND(G11*VLOOKUP(F11,GiaDinh!$A$14:$C$16,3,FALSE),1) | J11: =(H11+4*G11+I11)/6 | K11: =(I11-H11)/6 | L11: =J11*GiaDinh!$B$5 | M11: Sơ đồ kiến trúc
A12: 3.2 | B12: Thiết kế cơ sở dữ liệu: ERD 3NF, DDL | C12: Thiết kế | D12: BE | E12: E | F12: L | G12: 12 | H12: =ROUND(G12*VLOOKUP(F12,GiaDinh!$A$14:$C$16,2,FALSE),1) | I12: =ROUND(G12*VLOOKUP(F12,GiaDinh!$A$14:$C$16,3,FALSE),1) | J12: =(H12+4*G12+I12)/6 | K12: =(I12-H12)/6 | L12: =J12*GiaDinh!$B$5 | M12: ERD, migration
A13: 3.3 | B13: Thiết kế API, đặc tả OpenAPI | C13: Thiết kế | D13: BE | E13: F | F13: L | G13: 10 | H13: =ROUND(G13*VLOOKUP(F13,GiaDinh!$A$14:$C$16,2,FALSE),1) | I13: =ROUND(G13*VLOOKUP(F13,GiaDinh!$A$14:$C$16,3,FALSE),1) | J13: =(H13+4*G13+I13)/6 | K13: =(I13-H13)/6 | L13: =J13*GiaDinh!$B$5 | M13: Đặc tả API
A14: 3.4 | B14: Thiết kế giao diện, hệ thống thiết kế | C14: Thiết kế | D14: FE | E14: F | F14: M | G14: 14 | H14: =ROUND(G14*VLOOKUP(F14,GiaDinh!$A$14:$C$16,2,FALSE),1) | I14: =ROUND(G14*VLOOKUP(F14,GiaDinh!$A$14:$C$16,3,FALSE),1) | J14: =(H14+4*G14+I14)/6 | K14: =(I14-H14)/6 | L14: =J14*GiaDinh!$B$5 | M14: Wireframe, design token
A15: 3.5 | B15: Thiết kế mô hình AI: đặc trưng, chỉ số | C15: Thiết kế | D15: FE | E15: G | F15: M | G15: 8 | H15: =ROUND(G15*VLOOKUP(F15,GiaDinh!$A$14:$C$16,2,FALSE),1) | I15: =ROUND(G15*VLOOKUP(F15,GiaDinh!$A$14:$C$16,3,FALSE),1) | J15: =(H15+4*G15+I15)/6 | K15: =(I15-H15)/6 | L15: =J15*GiaDinh!$B$5 | M15: Tài liệu mô hình
A16: 4.1.1 | B16: Backend sách, tác giả, thể loại, bản sao | C16: Phát triển | D16: BE | E16: H | F16: M | G16: 18 | H16: =ROUND(G16*VLOOKUP(F16,GiaDinh!$A$14:$C$16,2,FALSE),1) | I16: =ROUND(G16*VLOOKUP(F16,GiaDinh!$A$14:$C$16,3,FALSE),1) | J16: =(H16+4*G16+I16)/6 | K16: =(I16-H16)/6 | L16: =J16*GiaDinh!$B$5 | M16: API quản lý kho
... A46: 7.4 | B46: Nghiệm thu, báo cáo cuối, bàn giao | C46: Quản lý dự án | D46: PM | E46: S | F46: L | G46: 10 | H46: =ROUND(G46*VLOOKUP(F46,GiaDinh!$A$14:$C$16,2,FALSE),1) | I46: =ROUND(G46*VLOOKUP(F46,GiaDinh!$A$14:$C$16,3,FALSE),1) | J46: =(H46+4*G46+I46)/6 | K46: =(I46-H46)/6 | L46: =J46*GiaDinh!$B$5 | M46: Biên bản nghiệm thu
B47: TỔNG (BAC) | G47: =SUM(G5:G46) | J47: =SUM(J5:J46) | L47: =SUM(L5:L46)
B48: Dự phòng quản lý | L48: =L47*GiaDinh!$B$9
B49: Ngân sách đề xuất (BAC + dự phòng) | L49: =L47+L48
B51: Tổng theo pha WBS cấp 1
A52: Mã | B52: Pha | J52: E (giờ) | K52: % giờ | L52: Chi phí (đ)
A53: 1 | B53: Khởi tạo | J53: =SUMIF($C$5:$C$46,B53,$J$5:$J$46) | K53: =J53/$J$47 | L53: =J53*GiaDinh!$B$5
A54: 2 | B54: Phân tích | J54: =SUMIF($C$5:$C$46,B54,$J$5:$J$46) | K54: =J54/$J$47 | L54: =J54*GiaDinh!$B$5
A55: 3 | B55: Thiết kế | J55: =SUMIF($C$5:$C$46,B55,$J$5:$J$46) | K55: =J55/$J$47 | L55: =J55*GiaDinh!$B$5
A56: 4 | B56: Phát triển | J56: =SUMIF($C$5:$C$46,B56,$J$5:$J$46) | K56: =J56/$J$47 | L56: =J56*GiaDinh!$B$5
A57: 5 | B57: Kiểm thử | J57: =SUMIF($C$5:$C$46,B57,$J$5:$J$46) | K57: =J57/$J$47 | L57: =J57*GiaDinh!$B$5
A58: 6 | B58: Triển khai | J58: =SUMIF($C$5:$C$46,B58,$J$5:$J$46) | K58: =J58/$J$47 | L58: =J58*GiaDinh!$B$5
A59: 7 | B59: Quản lý dự án | J59: =SUMIF($C$5:$C$46,B59,$J$5:$J$46) | K59: =J59/$J$47 | L59: =J59*GiaDinh!$B$5

Sheet CPM
A1: Lập lịch và đường găng (CPM)
A2: ES, EF tính xuôi; LS, LF tính ngược; Slack = LS - ES. Quan hệ FS và SS có độ trễ (lag). Đơn vị: tuần.
A4: Mã | B4: Hoạt động | C4: Thời lượng (tuần) | D4: Phụ thuộc (tiền nhiệm) | E4: ES | F4: EF | G4: LS | H4: LF | I4: Slack | J4: Găng?
A5: A | B5: Khởi tạo, SOW | C5: 1 | D5: - | E5: =MAX(0) | F5: =E5+C5 | G5: =H5-C5 | H5: =MIN($F$24,G6-0+C5,G7-0) | I5: =G5-E5 | J5: =IF(I5=0,"GĂNG","")
A6: C | B6: Khảo sát nghiệp vụ | C6: 1 | D6: A(SS) | E6: =MAX(0,E5+0) | F6: =E6+C6 | G6: =H6-C6 | H6: =MIN($F$24,G8-0) | I6: =G6-E6 | J6: =IF(I6=0,"GĂNG","")
A7: B | B7: Dựng môi trường | C7: 1 | D7: A(FS) | E7: =MAX(0,F5+0) | F7: =E7+C7 | G7: =H7-C7 | H7: =MIN($F$24,G12-0) | I7: =G7-E7 | J7: =IF(I7=0,"GĂNG","")
A8: D | B8: Phân tích: SRS, User Story | C8: 2 | D8: C(FS) | E8: =MAX(0,F6+0) | F8: =E8+C8 | G8: =H8-C8 | H8: =MIN($F$24,G9-1+C8,G10-2+C8,G11-2+C8) | I8: =G8-E8 | J8: =IF(I8=0,"GĂNG","")
A9: E | B9: Thiết kế kiến trúc, CSDL | C9: 2 | D9: D(SS+1) | E9: =MAX(0,E8+1) | F9: =E9+C9 | G9: =H9-C9 | H9: =MIN($F$24,G12-0) | I9: =G9-E9 | J9: =IF(I9=0,"GĂNG","")
A10: F | B10: Thiết kế API, giao diện | C10: 2 | D10: D(SS+2) | E10: =MAX(0,E8+2) | F10: =E10+C10 | G10: =H10-C10 | H10: =MIN($F$24,G14-0) | I10: =G10-E10 | J10: =IF(I10=0,"GĂNG","")
A11: G | B11: Thiết kế mô hình AI | C11: 1 | D11: D(SS+2) | E11: =MAX(0,E8+2) | F11: =E11+C11 | G11: =H11-C11 | H11: =MIN($F$24,G16-0) | I11: =G11-E11 | J11: =IF(I11=0,"GĂNG","")
A12: H | B12: Backend nền: auth, sách, seed | C12: 4 | D12: E(FS), B(FS) | E12: =MAX(0,F9+0,F7+0) | F12: =E12+C12 | G12: =H12-C12 | H12: =MIN($F$24,G13-1+C12,G14-1+C12,G18-2+C12,G20-0) | I12: =G12-E12 | J12: =IF(I12=0,"GĂNG","")
A13: I | B13: Backend mượn trả, phạt, tìm kiếm | C13: 4 | D13: H(SS+1) | E13: =MAX(0,E12+1) | F13: =E13+C13 | G13: =H13-C13 | H13: =MIN($F$24,G16-2+C13,G17-0) | I13: =G13-E13 | J13: =IF(I13=0,"GĂNG","")
A14: J | B14: Frontend khung, tra cứu, kho | C14: 4 | D14: F(FS), H(SS+1) | E14: =MAX(0,F10+0,E12+1) | F14: =E14+C14 | G14: =H14-C14 | H14: =MIN($F$24,G15-0) | I14: =G14-E14 | J14: =IF(I14=0,"GĂNG","")
A15: K | B15: Frontend quầy, báo cáo | C15: 3 | D15: J(FS) | E15: =MAX(0,F14+0) | F15: =E15+C15 | G15: =H15-C15 | H15: =MIN($F$24,G17-0) | I15: =G15-E15 | J15: =IF(I15=0,"GĂNG","")
A16: L | B16: AI gợi ý và dự báo | C16: 5 | D16: G(FS), I(SS+2) | E16: =MAX(0,F11+0,E13+2) | F16: =E16+C16 | G16: =H16-C16 | H16: =MIN($F$24,G17-0) | I16: =G16-E16 | J16: =IF(I16=0,"GĂNG","")
A17: M | B17: Tích hợp Backend, AI, Frontend | C17: 2 | D17: I(FS), K(FS), L(FS) | E17: =MAX(0,F13+0,F15+0,F16+0) | F17: =E17+C17 | G17: =H17-C17 | H17: =MIN($F$24,G19-1+C17,G22-0+C17) | I17: =G17-E17 | J17: =IF(I17=0,"GĂNG","")
A18: N | B18: Kiểm thử đơn vị, tích hợp | C18: 5 | D18: H(SS+2) | E18: =MAX(0,E12+2) | F18: =E18+C18 | G18: =H18-C18 | H18: =MIN($F$24,G19-0) | I18: =G18-E18 | J18: =IF(I18=0,"GĂNG","")
A19: O | B19: Kiểm thử hệ thống, UAT | C19: 2 | D19: M(SS+1), N(FS) | E19: =MAX(0,E17+1,F18+0) | F19: =E19+C19 | G19: =H19-C19 | H19: =MIN($F$24,G21-1+C19) | I19: =G19-E19 | J19: =IF(I19=0,"GĂNG","")
A20: Q | B20: Docker, CI/CD | C20: 2 | D20: H(FS) | E20: =MAX(0,F12+0) | F20: =E20+C20 | G20: =H20-C20 | H20: =MIN($F$24,G21-0) | I20: =G20-E20 | J20: =IF(I20=0,"GĂNG","")
A21: P | B21: Triển khai cloud, vận hành thử | C21: 1 | D21: O(SS+1), Q(FS) | E21: =MAX(0,E19+1,F20+0) | F21: =E21+C21 | G21: =H21-C21 | H21: =MIN($F$24,G23-0) | I21: =G21-E21 | J21: =IF(I21=0,"GĂNG","")
A22: R | B22: Tài liệu, đào tạo thủ thư | C22: 2 | D22: M(SS) | E22: =MAX(0,E17+0) | F22: =E22+C22 | G22: =H22-C22 | H22: =MIN($F$24,G23-0) | I22: =G22-E22 | J22: =IF(I22=0,"GĂNG","")
A23: S | B23: Nghiệm thu, bàn giao | C23: 1 | D23: P(FS), R(FS) | E23: =MAX(0,F21+0,F22+0) | F23: =E23+C23 | G23: =H23-C23 | H23: =MIN($F$24) | I23: =G23-E23 | J23: =IF(I23=0,"GĂNG","")
B24: Thời gian dự án (tuần) | F24: =MAX(F5:F23)
A27: Các đường găng (chuỗi hoạt động có Slack 0 nối nhau bằng ràng buộc chặt)
A28: Đường 1: | B28: A → C → D → E → H → I → L → M → O → P → S
A29: Đường 2: | B29: A → C → D → E → H → J → K → M → O → P → S
A30: Đường 3: | B30: A → C → D → F → J → K → M → O → P → S

Sheet PERT
A1: Ước lượng 3 điểm cho hoạt động và xác suất đúng hạn
A2: E = (a + 4m + b) / 6; Var = ((b - a) / 6)^2. Thời gian lịch kỳ vọng = thời gian CPM + tổng (E - m) trên đường găng chính.
A4: Mã | B4: Hoạt động | C4: Mức | D4: a (lạc quan) | E4: m (khả dĩ) | F4: b (bi quan) | G4: E | H4: Phương sai | I4: Trên đường găng chính?
A5: A | B5: Khởi tạo, SOW | C5: L | D5: =ROUND(E5*VLOOKUP(C5,GiaDinh!$E$14:$G$16,2,FALSE),2) | E5: =CPM!C5 | F5: =ROUND(E5*VLOOKUP(C5,GiaDinh!$E$14:$G$16,3,FALSE),2) | G5: =(D5+4*E5+F5)/6 | H5: =((F5-D5)/6)^2 | I5: x
A6: C | B6: Khảo sát nghiệp vụ | C6: L | D6: =ROUND(E6*VLOOKUP(C6,GiaDinh!$E$14:$G$16,2,FALSE),2) | E6: =CPM!C6 | F6: =ROUND(E6*VLOOKUP(C6,GiaDinh!$E$14:$G$16,3,FALSE),2) | G6: =(D6+4*E6+F6)/6 | H6: =((F6-D6)/6)^2 | I6: x
A7: B | B7: Dựng môi trường | C7: L | D7: =ROUND(E7*VLOOKUP(C7,GiaDinh!$E$14:$G$16,2,FALSE),2) | E7: =CPM!C7 | F7: =ROUND(E7*VLOOKUP(C7,GiaDinh!$E$14:$G$16,3,FALSE),2) | G7: =(D7+4*E7+F7)/6 | H7: =((F7-D7)/6)^2
A8: D | B8: Phân tích: SRS, User Story | C8: M | D8: =ROUND(E8*VLOOKUP(C8,GiaDinh!$E$14:$G$16,2,FALSE),2) | E8: =CPM!C8 | F8: =ROUND(E8*VLOOKUP(C8,GiaDinh!$E$14:$G$16,3,FALSE),2) | G8: =(D8+4*E8+F8)/6 | H8: =((F8-D8)/6)^2 | I8: x
A9: E | B9: Thiết kế kiến trúc, CSDL | C9: L | D9: =ROUND(E9*VLOOKUP(C9,GiaDinh!$E$14:$G$16,2,FALSE),2) | E9: =CPM!C9 | F9: =ROUND(E9*VLOOKUP(C9,GiaDinh!$E$14:$G$16,3,FALSE),2) | G9: =(D9+4*E9+F9)/6 | H9: =((F9-D9)/6)^2 | I9: x
A10: F | B10: Thiết kế API, giao diện | C10: L | D10: =ROUND(E10*VLOOKUP(C10,GiaDinh!$E$14:$G$16,2,FALSE),2) | E10: =CPM!C10 | F10: =ROUND(E10*VLOOKUP(C10,GiaDinh!$E$14:$G$16,3,FALSE),2) | G10: =(D10+4*E10+F10)/6 | H10: =((F10-D10)/6)^2
A11: G | B11: Thiết kế mô hình AI | C11: L | D11: =ROUND(E11*VLOOKUP(C11,GiaDinh!$E$14:$G$16,2,FALSE),2) | E11: =CPM!C11 | F11: =ROUND(E11*VLOOKUP(C11,GiaDinh!$E$14:$G$16,3,FALSE),2) | G11: =(D11+4*E11+F11)/6 | H11: =((F11-D11)/6)^2
A12: H | B12: Backend nền: auth, sách, seed | C12: H | D12: =ROUND(E12*VLOOKUP(C12,GiaDinh!$E$14:$G$16,2,FALSE),2) | E12: =CPM!C12 | F12: =ROUND(E12*VLOOKUP(C12,GiaDinh!$E$14:$G$16,3,FALSE),2) | G12: =(D12+4*E12+F12)/6 | H12: =((F12-D12)/6)^2 | I12: x
A13: I | B13: Backend mượn trả, phạt, tìm kiếm | C13: H | D13: =ROUND(E13*VLOOKUP(C13,GiaDinh!$E$14:$G$16,2,FALSE),2) | E13: =CPM!C13 | F13: =ROUND(E13*VLOOKUP(C13,GiaDinh!$E$14:$G$16,3,FALSE),2) | G13: =(D13+4*E13+F13)/6 | H13: =((F13-D13)/6)^2 | I13: x
A14: J | B14: Frontend khung, tra cứu, kho | C14: M | D14: =ROUND(E14*VLOOKUP(C14,GiaDinh!$E$14:$G$16,2,FALSE),2) | E14: =CPM!C14 | F14: =ROUND(E14*VLOOKUP(C14,GiaDinh!$E$14:$G$16,3,FALSE),2) | G14: =(D14+4*E14+F14)/6 | H14: =((F14-D14)/6)^2
A15: K | B15: Frontend quầy, báo cáo | C15: M | D15: =ROUND(E15*VLOOKUP(C15,GiaDinh!$E$14:$G$16,2,FALSE),2) | E15: =CPM!C15 | F15: =ROUND(E15*VLOOKUP(C15,GiaDinh!$E$14:$G$16,3,FALSE),2) | G15: =(D15+4*E15+F15)/6 | H15: =((F15-D15)/6)^2
A16: L | B16: AI gợi ý và dự báo | C16: H | D16: =ROUND(E16*VLOOKUP(C16,GiaDinh!$E$14:$G$16,2,FALSE),2) | E16: =CPM!C16 | F16: =ROUND(E16*VLOOKUP(C16,GiaDinh!$E$14:$G$16,3,FALSE),2) | G16: =(D16+4*E16+F16)/6 | H16: =((F16-D16)/6)^2 | I16: x
A17: M | B17: Tích hợp Backend, AI, Frontend | C17: H | D17: =ROUND(E17*VLOOKUP(C17,GiaDinh!$E$14:$G$16,2,FALSE),2) | E17: =CPM!C17 | F17: =ROUND(E17*VLOOKUP(C17,GiaDinh!$E$14:$G$16,3,FALSE),2) | G17: =(D17+4*E17+F17)/6 | H17: =((F17-D17)/6)^2 | I17: x
A18: N | B18: Kiểm thử đơn vị, tích hợp | C18: M | D18: =ROUND(E18*VLOOKUP(C18,GiaDinh!$E$14:$G$16,2,FALSE),2) | E18: =CPM!C18 | F18: =ROUND(E18*VLOOKUP(C18,GiaDinh!$E$14:$G$16,3,FALSE),2) | G18: =(D18+4*E18+F18)/6 | H18: =((F18-D18)/6)^2
A19: O | B19: Kiểm thử hệ thống, UAT | C19: M | D19: =ROUND(E19*VLOOKUP(C19,GiaDinh!$E$14:$G$16,2,FALSE),2) | E19: =CPM!C19 | F19: =ROUND(E19*VLOOKUP(C19,GiaDinh!$E$14:$G$16,3,FALSE),2) | G19: =(D19+4*E19+F19)/6 | H19: =((F19-D19)/6)^2 | I19: x
A20: Q | B20: Docker, CI/CD | C20: L | D20: =ROUND(E20*VLOOKUP(C20,GiaDinh!$E$14:$G$16,2,FALSE),2) | E20: =CPM!C20 | F20: =ROUND(E20*VLOOKUP(C20,GiaDinh!$E$14:$G$16,3,FALSE),2) | G20: =(D20+4*E20+F20)/6 | H20: =((F20-D20)/6)^2
A21: P | B21: Triển khai cloud, vận hành thử | C21: M | D21: =ROUND(E21*VLOOKUP(C21,GiaDinh!$E$14:$G$16,2,FALSE),2) | E21: =CPM!C21 | F21: =ROUND(E21*VLOOKUP(C21,GiaDinh!$E$14:$G$16,3,FALSE),2) | G21: =(D21+4*E21+F21)/6 | H21: =((F21-D21)/6)^2 | I21: x
A22: R | B22: Tài liệu, đào tạo thủ thư | C22: L | D22: =ROUND(E22*VLOOKUP(C22,GiaDinh!$E$14:$G$16,2,FALSE),2) | E22: =CPM!C22 | F22: =ROUND(E22*VLOOKUP(C22,GiaDinh!$E$14:$G$16,3,FALSE),2) | G22: =(D22+4*E22+F22)/6 | H22: =((F22-D22)/6)^2
A23: S | B23: Nghiệm thu, bàn giao | C23: L | D23: =ROUND(E23*VLOOKUP(C23,GiaDinh!$E$14:$G$16,2,FALSE),2) | E23: =CPM!C23 | F23: =ROUND(E23*VLOOKUP(C23,GiaDinh!$E$14:$G$16,3,FALSE),2) | G23: =(D23+4*E23+F23)/6 | H23: =((F23-D23)/6)^2 | I23: x
B25: Đường găng chính (độ bất định lớn nhất): A → C → D → E → H → I → L → M → O → P → S
B26: Thời gian CPM (tuần) | G26: =CPM!$F$24
B27: Thời gian lịch kỳ vọng (tuần) | G27: =G26+SUMPRODUCT((I5:I23="x")*(G5:G23-E5:E23))
B28: Độ lệch chuẩn (tuần) | G28: =SQRT(SUMPRODUCT((I5:I23="x")*H5:H23))
B29: Xác suất hoàn thành trong 16 tuần | G29: =NORMSDIST((16-G27)/G28)
B30: Xác suất hoàn thành trong 17 tuần | G30: =NORMSDIST((17-G27)/G28)
B31: Xác suất hoàn thành trong 18 tuần | G31: =NORMSDIST((18-G27)/G28)

Sheet Gantt
A1: Biểu đồ Gantt theo tuần
A2: Ô có số 1 nghĩa là hoạt động chạy trong tuần đó. Đỏ: hoạt động găng; xanh: có độ dự trữ.
A4: Mã | B4: Hoạt động | C4: Bắt đầu (ES) | D4: Kết thúc (EF) | E4: Găng? | F4: T1 | G4: T2 | H4: T3 | I4: T4 | J4: T5 | K4: T6 | L4: T7 | M4: T8 | N4: T9 | O4: T10 | P4: T11 | Q4: T12 | R4: T13 | S4: T14 | T4: T15 | U4: T16
A5: A | B5: Khởi tạo, SOW | C5: =CPM!E5 | D5: =CPM!F5 | E5: =CPM!J5 | F5: =IF(AND(1>$C5,1<=$D5),1,0) | G5: =IF(AND(2>$C5,2<=$D5),1,0) | H5: =IF(AND(3>$C5,3<=$D5),1,0) | I5: =IF(AND(4>$C5,4<=$D5),1,0) | J5: =IF(AND(5>$C5,5<=$D5),1,0) | K5: =IF(AND(6>$C5,6<=$D5),1,0) | L5: =IF(AND(7>$C5,7<=$D5),1,0) | M5: =IF(AND(8>$C5,8<=$D5),1,0) | N5: =IF(AND(9>$C5,9<=$D5),1,0) | O5: =IF(AND(10>$C5,10<=$D5),1,0) | P5: =IF(AND(11>$C5,11<=$D5),1,0) | Q5: =IF(AND(12>$C5,12<=$D5),1,0) | R5: =IF(AND(13>$C5,13<=$D5),1,0) | S5: =IF(AND(14>$C5,14<=$D5),1,0) | T5: =IF(AND(15>$C5,15<=$D5),1,0) | U5: =IF(AND(16>$C5,16<=$D5),1,0)
A6: C | B6: Khảo sát nghiệp vụ | C6: =CPM!E6 | D6: =CPM!F6 | E6: =CPM!J6 | F6: =IF(AND(1>$C6,1<=$D6),1,0) | G6: =IF(AND(2>$C6,2<=$D6),1,0) | H6: =IF(AND(3>$C6,3<=$D6),1,0) | I6: =IF(AND(4>$C6,4<=$D6),1,0) | J6: =IF(AND(5>$C6,5<=$D6),1,0) | K6: =IF(AND(6>$C6,6<=$D6),1,0) | L6: =IF(AND(7>$C6,7<=$D6),1,0) | M6: =IF(AND(8>$C6,8<=$D6),1,0) | N6: =IF(AND(9>$C6,9<=$D6),1,0) | O6: =IF(AND(10>$C6,10<=$D6),1,0) | P6: =IF(AND(11>$C6,11<=$D6),1,0) | Q6: =IF(AND(12>$C6,12<=$D6),1,0) | R6: =IF(AND(13>$C6,13<=$D6),1,0) | S6: =IF(AND(14>$C6,14<=$D6),1,0) | T6: =IF(AND(15>$C6,15<=$D6),1,0) | U6: =IF(AND(16>$C6,16<=$D6),1,0)
A7: B | B7: Dựng môi trường | C7: =CPM!E7 | D7: =CPM!F7 | E7: =CPM!J7 | F7: =IF(AND(1>$C7,1<=$D7),1,0) | G7: =IF(AND(2>$C7,2<=$D7),1,0) | H7: =IF(AND(3>$C7,3<=$D7),1,0) | I7: =IF(AND(4>$C7,4<=$D7),1,0) | J7: =IF(AND(5>$C7,5<=$D7),1,0) | K7: =IF(AND(6>$C7,6<=$D7),1,0) | L7: =IF(AND(7>$C7,7<=$D7),1,0) | M7: =IF(AND(8>$C7,8<=$D7),1,0) | N7: =IF(AND(9>$C7,9<=$D7),1,0) | O7: =IF(AND(10>$C7,10<=$D7),1,0) | P7: =IF(AND(11>$C7,11<=$D7),1,0) | Q7: =IF(AND(12>$C7,12<=$D7),1,0) | R7: =IF(AND(13>$C7,13<=$D7),1,0) | S7: =IF(AND(14>$C7,14<=$D7),1,0) | T7: =IF(AND(15>$C7,15<=$D7),1,0) | U7: =IF(AND(16>$C7,16<=$D7),1,0)
A8: D | B8: Phân tích: SRS, User Story | C8: =CPM!E8 | D8: =CPM!F8 | E8: =CPM!J8 | F8: =IF(AND(1>$C8,1<=$D8),1,0) | G8: =IF(AND(2>$C8,2<=$D8),1,0) | H8: =IF(AND(3>$C8,3<=$D8),1,0) | I8: =IF(AND(4>$C8,4<=$D8),1,0) | J8: =IF(AND(5>$C8,5<=$D8),1,0) | K8: =IF(AND(6>$C8,6<=$D8),1,0) | L8: =IF(AND(7>$C8,7<=$D8),1,0) | M8: =IF(AND(8>$C8,8<=$D8),1,0) | N8: =IF(AND(9>$C8,9<=$D8),1,0) | O8: =IF(AND(10>$C8,10<=$D8),1,0) | P8: =IF(AND(11>$C8,11<=$D8),1,0) | Q8: =IF(AND(12>$C8,12<=$D8),1,0) | R8: =IF(AND(13>$C8,13<=$D8),1,0) | S8: =IF(AND(14>$C8,14<=$D8),1,0) | T8: =IF(AND(15>$C8,15<=$D8),1,0) | U8: =IF(AND(16>$C8,16<=$D8),1,0)
A9: E | B9: Thiết kế kiến trúc, CSDL | C9: =CPM!E9 | D9: =CPM!F9 | E9: =CPM!J9 | F9: =IF(AND(1>$C9,1<=$D9),1,0) | G9: =IF(AND(2>$C9,2<=$D9),1,0) | H9: =IF(AND(3>$C9,3<=$D9),1,0) | I9: =IF(AND(4>$C9,4<=$D9),1,0) | J9: =IF(AND(5>$C9,5<=$D9),1,0) | K9: =IF(AND(6>$C9,6<=$D9),1,0) | L9: =IF(AND(7>$C9,7<=$D9),1,0) | M9: =IF(AND(8>$C9,8<=$D9),1,0) | N9: =IF(AND(9>$C9,9<=$D9),1,0) | O9: =IF(AND(10>$C9,10<=$D9),1,0) | P9: =IF(AND(11>$C9,11<=$D9),1,0) | Q9: =IF(AND(12>$C9,12<=$D9),1,0) | R9: =IF(AND(13>$C9,13<=$D9),1,0) | S9: =IF(AND(14>$C9,14<=$D9),1,0) | T9: =IF(AND(15>$C9,15<=$D9),1,0) | U9: =IF(AND(16>$C9,16<=$D9),1,0)
A10: F | B10: Thiết kế API, giao diện | C10: =CPM!E10 | D10: =CPM!F10 | E10: =CPM!J10 | F10: =IF(AND(1>$C10,1<=$D10),1,0) | G10: =IF(AND(2>$C10,2<=$D10),1,0) | H10: =IF(AND(3>$C10,3<=$D10),1,0) | I10: =IF(AND(4>$C10,4<=$D10),1,0) | J10: =IF(AND(5>$C10,5<=$D10),1,0) | K10: =IF(AND(6>$C10,6<=$D10),1,0) | L10: =IF(AND(7>$C10,7<=$D10),1,0) | M10: =IF(AND(8>$C10,8<=$D10),1,0) | N10: =IF(AND(9>$C10,9<=$D10),1,0) | O10: =IF(AND(10>$C10,10<=$D10),1,0) | P10: =IF(AND(11>$C10,11<=$D10),1,0) | Q10: =IF(AND(12>$C10,12<=$D10),1,0) | R10: =IF(AND(13>$C10,13<=$D10),1,0) | S10: =IF(AND(14>$C10,14<=$D10),1,0) | T10: =IF(AND(15>$C10,15<=$D10),1,0) | U10: =IF(AND(16>$C10,16<=$D10),1,0)
A11: G | B11: Thiết kế mô hình AI | C11: =CPM!E11 | D11: =CPM!F11 | E11: =CPM!J11 | F11: =IF(AND(1>$C11,1<=$D11),1,0) | G11: =IF(AND(2>$C11,2<=$D11),1,0) | H11: =IF(AND(3>$C11,3<=$D11),1,0) | I11: =IF(AND(4>$C11,4<=$D11),1,0) | J11: =IF(AND(5>$C11,5<=$D11),1,0) | K11: =IF(AND(6>$C11,6<=$D11),1,0) | L11: =IF(AND(7>$C11,7<=$D11),1,0) | M11: =IF(AND(8>$C11,8<=$D11),1,0) | N11: =IF(AND(9>$C11,9<=$D11),1,0) | O11: =IF(AND(10>$C11,10<=$D11),1,0) | P11: =IF(AND(11>$C11,11<=$D11),1,0) | Q11: =IF(AND(12>$C11,12<=$D11),1,0) | R11: =IF(AND(13>$C11,13<=$D11),1,0) | S11: =IF(AND(14>$C11,14<=$D11),1,0) | T11: =IF(AND(15>$C11,15<=$D11),1,0) | U11: =IF(AND(16>$C11,16<=$D11),1,0)
A12: H | B12: Backend nền: auth, sách, seed | C12: =CPM!E12 | D12: =CPM!F12 | E12: =CPM!J12 | F12: =IF(AND(1>$C12,1<=$D12),1,0) | G12: =IF(AND(2>$C12,2<=$D12),1,0) | H12: =IF(AND(3>$C12,3<=$D12),1,0) | I12: =IF(AND(4>$C12,4<=$D12),1,0) | J12: =IF(AND(5>$C12,5<=$D12),1,0) | K12: =IF(AND(6>$C12,6<=$D12),1,0) | L12: =IF(AND(7>$C12,7<=$D12),1,0) | M12: =IF(AND(8>$C12,8<=$D12),1,0) | N12: =IF(AND(9>$C12,9<=$D12),1,0) | O12: =IF(AND(10>$C12,10<=$D12),1,0) | P12: =IF(AND(11>$C12,11<=$D12),1,0) | Q12: =IF(AND(12>$C12,12<=$D12),1,0) | R12: =IF(AND(13>$C12,13<=$D12),1,0) | S12: =IF(AND(14>$C12,14<=$D12),1,0) | T12: =IF(AND(15>$C12,15<=$D12),1,0) | U12: =IF(AND(16>$C12,16<=$D12),1,0)
A13: I | B13: Backend mượn trả, phạt, tìm kiếm | C13: =CPM!E13 | D13: =CPM!F13 | E13: =CPM!J13 | F13: =IF(AND(1>$C13,1<=$D13),1,0) | G13: =IF(AND(2>$C13,2<=$D13),1,0) | H13: =IF(AND(3>$C13,3<=$D13),1,0) | I13: =IF(AND(4>$C13,4<=$D13),1,0) | J13: =IF(AND(5>$C13,5<=$D13),1,0) | K13: =IF(AND(6>$C13,6<=$D13),1,0) | L13: =IF(AND(7>$C13,7<=$D13),1,0) | M13: =IF(AND(8>$C13,8<=$D13),1,0) | N13: =IF(AND(9>$C13,9<=$D13),1,0) | O13: =IF(AND(10>$C13,10<=$D13),1,0) | P13: =IF(AND(11>$C13,11<=$D13),1,0) | Q13: =IF(AND(12>$C13,12<=$D13),1,0) | R13: =IF(AND(13>$C13,13<=$D13),1,0) | S13: =IF(AND(14>$C13,14<=$D13),1,0) | T13: =IF(AND(15>$C13,15<=$D13),1,0) | U13: =IF(AND(16>$C13,16<=$D13),1,0)
A14: J | B14: Frontend khung, tra cứu, kho | C14: =CPM!E14 | D14: =CPM!F14 | E14: =CPM!J14 | F14: =IF(AND(1>$C14,1<=$D14),1,0) | G14: =IF(AND(2>$C14,2<=$D14),1,0) | H14: =IF(AND(3>$C14,3<=$D14),1,0) | I14: =IF(AND(4>$C14,4<=$D14),1,0) | J14: =IF(AND(5>$C14,5<=$D14),1,0) | K14: =IF(AND(6>$C14,6<=$D14),1,0) | L14: =IF(AND(7>$C14,7<=$D14),1,0) | M14: =IF(AND(8>$C14,8<=$D14),1,0) | N14: =IF(AND(9>$C14,9<=$D14),1,0) | O14: =IF(AND(10>$C14,10<=$D14),1,0) | P14: =IF(AND(11>$C14,11<=$D14),1,0) | Q14: =IF(AND(12>$C14,12<=$D14),1,0) | R14: =IF(AND(13>$C14,13<=$D14),1,0) | S14: =IF(AND(14>$C14,14<=$D14),1,0) | T14: =IF(AND(15>$C14,15<=$D14),1,0) | U14: =IF(AND(16>$C14,16<=$D14),1,0)
A15: K | B15: Frontend quầy, báo cáo | C15: =CPM!E15 | D15: =CPM!F15 | E15: =CPM!J15 | F15: =IF(AND(1>$C15,1<=$D15),1,0) | G15: =IF(AND(2>$C15,2<=$D15),1,0) | H15: =IF(AND(3>$C15,3<=$D15),1,0) | I15: =IF(AND(4>$C15,4<=$D15),1,0) | J15: =IF(AND(5>$C15,5<=$D15),1,0) | K15: =IF(AND(6>$C15,6<=$D15),1,0) | L15: =IF(AND(7>$C15,7<=$D15),1,0) | M15: =IF(AND(8>$C15,8<=$D15),1,0) | N15: =IF(AND(9>$C15,9<=$D15),1,0) | O15: =IF(AND(10>$C15,10<=$D15),1,0) | P15: =IF(AND(11>$C15,11<=$D15),1,0) | Q15: =IF(AND(12>$C15,12<=$D15),1,0) | R15: =IF(AND(13>$C15,13<=$D15),1,0) | S15: =IF(AND(14>$C15,14<=$D15),1,0) | T15: =IF(AND(15>$C15,15<=$D15),1,0) | U15: =IF(AND(16>$C15,16<=$D15),1,0)
A16: L | B16: AI gợi ý và dự báo | C16: =CPM!E16 | D16: =CPM!F16 | E16: =CPM!J16 | F16: =IF(AND(1>$C16,1<=$D16),1,0) | G16: =IF(AND(2>$C16,2<=$D16),1,0) | H16: =IF(AND(3>$C16,3<=$D16),1,0) | I16: =IF(AND(4>$C16,4<=$D16),1,0) | J16: =IF(AND(5>$C16,5<=$D16),1,0) | K16: =IF(AND(6>$C16,6<=$D16),1,0) | L16: =IF(AND(7>$C16,7<=$D16),1,0) | M16: =IF(AND(8>$C16,8<=$D16),1,0) | N16: =IF(AND(9>$C16,9<=$D16),1,0) | O16: =IF(AND(10>$C16,10<=$D16),1,0) | P16: =IF(AND(11>$C16,11<=$D16),1,0) | Q16: =IF(AND(12>$C16,12<=$D16),1,0) | R16: =IF(AND(13>$C16,13<=$D16),1,0) | S16: =IF(AND(14>$C16,14<=$D16),1,0) | T16: =IF(AND(15>$C16,15<=$D16),1,0) | U16: =IF(AND(16>$C16,16<=$D16),1,0)
... A23: S | B23: Nghiệm thu, bàn giao | C23: =CPM!E23 | D23: =CPM!F23 | E23: =CPM!J23 | F23: =IF(AND(1>$C23,1<=$D23),1,0) | G23: =IF(AND(2>$C23,2<=$D23),1,0) | H23: =IF(AND(3>$C23,3<=$D23),1,0) | I23: =IF(AND(4>$C23,4<=$D23),1,0) | J23: =IF(AND(5>$C23,5<=$D23),1,0) | K23: =IF(AND(6>$C23,6<=$D23),1,0) | L23: =IF(AND(7>$C23,7<=$D23),1,0) | M23: =IF(AND(8>$C23,8<=$D23),1,0) | N23: =IF(AND(9>$C23,9<=$D23),1,0) | O23: =IF(AND(10>$C23,10<=$D23),1,0) | P23: =IF(AND(11>$C23,11<=$D23),1,0) | Q23: =IF(AND(12>$C23,12<=$D23),1,0) | R23: =IF(AND(13>$C23,13<=$D23),1,0) | S23: =IF(AND(14>$C23,14<=$D23),1,0) | T23: =IF(AND(15>$C23,15<=$D23),1,0) | U23: =IF(AND(16>$C23,16<=$D23),1,0)
B25: Mốc (milestone)
A26: T2 | B26: M1: Hiến chương, SOW được duyệt
A27: T3 | B27: M2: SRS và 20 User Story được duyệt
A28: T5 | B28: M3: Thiết kế (kiến trúc, CSDL, API, giao diện) được duyệt
A29: T9 | B29: M4: Backend và Frontend lõi chạy được (mượn trả đầu-cuối)
A30: T12 | B30: M5: AI hoàn chỉnh, đạt ngưỡng chỉ số
A31: T14 | B31: M6: Tích hợp xong, bắt đầu kiểm thử hệ thống
A32: T15 | B32: M7: Qua UAT, triển khai cloud
A33: T16 | B33: M8: Nghiệm thu và bàn giao

Sheet NguonLuc
A1: Giờ kế hoạch theo tuần (nền của PV) và tải theo vai trò
A2: Gói công việc trải đều trong cửa sổ [ES, EF] của hoạt động (lịch sớm). Công việc duy trì (LOE) trải đều 16 tuần, riêng 7.3 dồn vào tuần 4, 8, 12, 16.
A4: Mã WBS | B4: Gói công việc | C4: Vai trò | D4: Hoạt động | E4: E (giờ) | F4: ES | G4: EF | H4: T1 | I4: T2 | J4: T3 | K4: T4 | L4: T5 | M4: T6 | N4: T7 | O4: T8 | P4: T9 | Q4: T10 | R4: T11 | S4: T12 | T4: T13 | U4: T14 | V4: T15 | W4: T16
A5: =WBS!A5 | B5: =WBS!B5 | C5: =WBS!D5 | D5: =WBS!E5 | E5: =WBS!J5 | F5: =CPM!E5 | G5: =CPM!F5 | H5: =IF(AND(1>$F5,1<=$G5),$E5/($G5-$F5),0) | I5: =IF(AND(2>$F5,2<=$G5),$E5/($G5-$F5),0) | J5: =IF(AND(3>$F5,3<=$G5),$E5/($G5-$F5),0) | K5: =IF(AND(4>$F5,4<=$G5),$E5/($G5-$F5),0) | L5: =IF(AND(5>$F5,5<=$G5),$E5/($G5-$F5),0) | M5: =IF(AND(6>$F5,6<=$G5),$E5/($G5-$F5),0) | N5: =IF(AND(7>$F5,7<=$G5),$E5/($G5-$F5),0) | O5: =IF(AND(8>$F5,8<=$G5),$E5/($G5-$F5),0) | P5: =IF(AND(9>$F5,9<=$G5),$E5/($G5-$F5),0) | Q5: =IF(AND(10>$F5,10<=$G5),$E5/($G5-$F5),0) | R5: =IF(AND(11>$F5,11<=$G5),$E5/($G5-$F5),0) | S5: =IF(AND(12>$F5,12<=$G5),$E5/($G5-$F5),0) | T5: =IF(AND(13>$F5,13<=$G5),$E5/($G5-$F5),0) | U5: =IF(AND(14>$F5,14<=$G5),$E5/($G5-$F5),0) | V5: =IF(AND(15>$F5,15<=$G5),$E5/($G5-$F5),0) | W5: =IF(AND(16>$F5,16<=$G5),$E5/($G5-$F5),0)
A6: =WBS!A6 | B6: =WBS!B6 | C6: =WBS!D6 | D6: =WBS!E6 | E6: =WBS!J6 | F6: =CPM!E5 | G6: =CPM!F5 | H6: =IF(AND(1>$F6,1<=$G6),$E6/($G6-$F6),0) | I6: =IF(AND(2>$F6,2<=$G6),$E6/($G6-$F6),0) | J6: =IF(AND(3>$F6,3<=$G6),$E6/($G6-$F6),0) | K6: =IF(AND(4>$F6,4<=$G6),$E6/($G6-$F6),0) | L6: =IF(AND(5>$F6,5<=$G6),$E6/($G6-$F6),0) | M6: =IF(AND(6>$F6,6<=$G6),$E6/($G6-$F6),0) | N6: =IF(AND(7>$F6,7<=$G6),$E6/($G6-$F6),0) | O6: =IF(AND(8>$F6,8<=$G6),$E6/($G6-$F6),0) | P6: =IF(AND(9>$F6,9<=$G6),$E6/($G6-$F6),0) | Q6: =IF(AND(10>$F6,10<=$G6),$E6/($G6-$F6),0) | R6: =IF(AND(11>$F6,11<=$G6),$E6/($G6-$F6),0) | S6: =IF(AND(12>$F6,12<=$G6),$E6/($G6-$F6),0) | T6: =IF(AND(13>$F6,13<=$G6),$E6/($G6-$F6),0) | U6: =IF(AND(14>$F6,14<=$G6),$E6/($G6-$F6),0) | V6: =IF(AND(15>$F6,15<=$G6),$E6/($G6-$F6),0) | W6: =IF(AND(16>$F6,16<=$G6),$E6/($G6-$F6),0)
A7: =WBS!A7 | B7: =WBS!B7 | C7: =WBS!D7 | D7: =WBS!E7 | E7: =WBS!J7 | F7: =CPM!E7 | G7: =CPM!F7 | H7: =IF(AND(1>$F7,1<=$G7),$E7/($G7-$F7),0) | I7: =IF(AND(2>$F7,2<=$G7),$E7/($G7-$F7),0) | J7: =IF(AND(3>$F7,3<=$G7),$E7/($G7-$F7),0) | K7: =IF(AND(4>$F7,4<=$G7),$E7/($G7-$F7),0) | L7: =IF(AND(5>$F7,5<=$G7),$E7/($G7-$F7),0) | M7: =IF(AND(6>$F7,6<=$G7),$E7/($G7-$F7),0) | N7: =IF(AND(7>$F7,7<=$G7),$E7/($G7-$F7),0) | O7: =IF(AND(8>$F7,8<=$G7),$E7/($G7-$F7),0) | P7: =IF(AND(9>$F7,9<=$G7),$E7/($G7-$F7),0) | Q7: =IF(AND(10>$F7,10<=$G7),$E7/($G7-$F7),0) | R7: =IF(AND(11>$F7,11<=$G7),$E7/($G7-$F7),0) | S7: =IF(AND(12>$F7,12<=$G7),$E7/($G7-$F7),0) | T7: =IF(AND(13>$F7,13<=$G7),$E7/($G7-$F7),0) | U7: =IF(AND(14>$F7,14<=$G7),$E7/($G7-$F7),0) | V7: =IF(AND(15>$F7,15<=$G7),$E7/($G7-$F7),0) | W7: =IF(AND(16>$F7,16<=$G7),$E7/($G7-$F7),0)
A8: =WBS!A8 | B8: =WBS!B8 | C8: =WBS!D8 | D8: =WBS!E8 | E8: =WBS!J8 | F8: =CPM!E6 | G8: =CPM!F6 | H8: =IF(AND(1>$F8,1<=$G8),$E8/($G8-$F8),0) | I8: =IF(AND(2>$F8,2<=$G8),$E8/($G8-$F8),0) | J8: =IF(AND(3>$F8,3<=$G8),$E8/($G8-$F8),0) | K8: =IF(AND(4>$F8,4<=$G8),$E8/($G8-$F8),0) | L8: =IF(AND(5>$F8,5<=$G8),$E8/($G8-$F8),0) | M8: =IF(AND(6>$F8,6<=$G8),$E8/($G8-$F8),0) | N8: =IF(AND(7>$F8,7<=$G8),$E8/($G8-$F8),0) | O8: =IF(AND(8>$F8,8<=$G8),$E8/($G8-$F8),0) | P8: =IF(AND(9>$F8,9<=$G8),$E8/($G8-$F8),0) | Q8: =IF(AND(10>$F8,10<=$G8),$E8/($G8-$F8),0) | R8: =IF(AND(11>$F8,11<=$G8),$E8/($G8-$F8),0) | S8: =IF(AND(12>$F8,12<=$G8),$E8/($G8-$F8),0) | T8: =IF(AND(13>$F8,13<=$G8),$E8/($G8-$F8),0) | U8: =IF(AND(14>$F8,14<=$G8),$E8/($G8-$F8),0) | V8: =IF(AND(15>$F8,15<=$G8),$E8/($G8-$F8),0) | W8: =IF(AND(16>$F8,16<=$G8),$E8/($G8-$F8),0)
A9: =WBS!A9 | B9: =WBS!B9 | C9: =WBS!D9 | D9: =WBS!E9 | E9: =WBS!J9 | F9: =CPM!E8 | G9: =CPM!F8 | H9: =IF(AND(1>$F9,1<=$G9),$E9/($G9-$F9),0) | I9: =IF(AND(2>$F9,2<=$G9),$E9/($G9-$F9),0) | J9: =IF(AND(3>$F9,3<=$G9),$E9/($G9-$F9),0) | K9: =IF(AND(4>$F9,4<=$G9),$E9/($G9-$F9),0) | L9: =IF(AND(5>$F9,5<=$G9),$E9/($G9-$F9),0) | M9: =IF(AND(6>$F9,6<=$G9),$E9/($G9-$F9),0) | N9: =IF(AND(7>$F9,7<=$G9),$E9/($G9-$F9),0) | O9: =IF(AND(8>$F9,8<=$G9),$E9/($G9-$F9),0) | P9: =IF(AND(9>$F9,9<=$G9),$E9/($G9-$F9),0) | Q9: =IF(AND(10>$F9,10<=$G9),$E9/($G9-$F9),0) | R9: =IF(AND(11>$F9,11<=$G9),$E9/($G9-$F9),0) | S9: =IF(AND(12>$F9,12<=$G9),$E9/($G9-$F9),0) | T9: =IF(AND(13>$F9,13<=$G9),$E9/($G9-$F9),0) | U9: =IF(AND(14>$F9,14<=$G9),$E9/($G9-$F9),0) | V9: =IF(AND(15>$F9,15<=$G9),$E9/($G9-$F9),0) | W9: =IF(AND(16>$F9,16<=$G9),$E9/($G9-$F9),0)
A10: =WBS!A10 | B10: =WBS!B10 | C10: =WBS!D10 | D10: =WBS!E10 | E10: =WBS!J10 | F10: =CPM!E8 | G10: =CPM!F8 | H10: =IF(AND(1>$F10,1<=$G10),$E10/($G10-$F10),0) | I10: =IF(AND(2>$F10,2<=$G10),$E10/($G10-$F10),0) | J10: =IF(AND(3>$F10,3<=$G10),$E10/($G10-$F10),0) | K10: =IF(AND(4>$F10,4<=$G10),$E10/($G10-$F10),0) | L10: =IF(AND(5>$F10,5<=$G10),$E10/($G10-$F10),0) | M10: =IF(AND(6>$F10,6<=$G10),$E10/($G10-$F10),0) | N10: =IF(AND(7>$F10,7<=$G10),$E10/($G10-$F10),0) | O10: =IF(AND(8>$F10,8<=$G10),$E10/($G10-$F10),0) | P10: =IF(AND(9>$F10,9<=$G10),$E10/($G10-$F10),0) | Q10: =IF(AND(10>$F10,10<=$G10),$E10/($G10-$F10),0) | R10: =IF(AND(11>$F10,11<=$G10),$E10/($G10-$F10),0) | S10: =IF(AND(12>$F10,12<=$G10),$E10/($G10-$F10),0) | T10: =IF(AND(13>$F10,13<=$G10),$E10/($G10-$F10),0) | U10: =IF(AND(14>$F10,14<=$G10),$E10/($G10-$F10),0) | V10: =IF(AND(15>$F10,15<=$G10),$E10/($G10-$F10),0) | W10: =IF(AND(16>$F10,16<=$G10),$E10/($G10-$F10),0)
A11: =WBS!A11 | B11: =WBS!B11 | C11: =WBS!D11 | D11: =WBS!E11 | E11: =WBS!J11 | F11: =CPM!E9 | G11: =CPM!F9 | H11: =IF(AND(1>$F11,1<=$G11),$E11/($G11-$F11),0) | I11: =IF(AND(2>$F11,2<=$G11),$E11/($G11-$F11),0) | J11: =IF(AND(3>$F11,3<=$G11),$E11/($G11-$F11),0) | K11: =IF(AND(4>$F11,4<=$G11),$E11/($G11-$F11),0) | L11: =IF(AND(5>$F11,5<=$G11),$E11/($G11-$F11),0) | M11: =IF(AND(6>$F11,6<=$G11),$E11/($G11-$F11),0) | N11: =IF(AND(7>$F11,7<=$G11),$E11/($G11-$F11),0) | O11: =IF(AND(8>$F11,8<=$G11),$E11/($G11-$F11),0) | P11: =IF(AND(9>$F11,9<=$G11),$E11/($G11-$F11),0) | Q11: =IF(AND(10>$F11,10<=$G11),$E11/($G11-$F11),0) | R11: =IF(AND(11>$F11,11<=$G11),$E11/($G11-$F11),0) | S11: =IF(AND(12>$F11,12<=$G11),$E11/($G11-$F11),0) | T11: =IF(AND(13>$F11,13<=$G11),$E11/($G11-$F11),0) | U11: =IF(AND(14>$F11,14<=$G11),$E11/($G11-$F11),0) | V11: =IF(AND(15>$F11,15<=$G11),$E11/($G11-$F11),0) | W11: =IF(AND(16>$F11,16<=$G11),$E11/($G11-$F11),0)
A12: =WBS!A12 | B12: =WBS!B12 | C12: =WBS!D12 | D12: =WBS!E12 | E12: =WBS!J12 | F12: =CPM!E9 | G12: =CPM!F9 | H12: =IF(AND(1>$F12,1<=$G12),$E12/($G12-$F12),0) | I12: =IF(AND(2>$F12,2<=$G12),$E12/($G12-$F12),0) | J12: =IF(AND(3>$F12,3<=$G12),$E12/($G12-$F12),0) | K12: =IF(AND(4>$F12,4<=$G12),$E12/($G12-$F12),0) | L12: =IF(AND(5>$F12,5<=$G12),$E12/($G12-$F12),0) | M12: =IF(AND(6>$F12,6<=$G12),$E12/($G12-$F12),0) | N12: =IF(AND(7>$F12,7<=$G12),$E12/($G12-$F12),0) | O12: =IF(AND(8>$F12,8<=$G12),$E12/($G12-$F12),0) | P12: =IF(AND(9>$F12,9<=$G12),$E12/($G12-$F12),0) | Q12: =IF(AND(10>$F12,10<=$G12),$E12/($G12-$F12),0) | R12: =IF(AND(11>$F12,11<=$G12),$E12/($G12-$F12),0) | S12: =IF(AND(12>$F12,12<=$G12),$E12/($G12-$F12),0) | T12: =IF(AND(13>$F12,13<=$G12),$E12/($G12-$F12),0) | U12: =IF(AND(14>$F12,14<=$G12),$E12/($G12-$F12),0) | V12: =IF(AND(15>$F12,15<=$G12),$E12/($G12-$F12),0) | W12: =IF(AND(16>$F12,16<=$G12),$E12/($G12-$F12),0)
A13: =WBS!A13 | B13: =WBS!B13 | C13: =WBS!D13 | D13: =WBS!E13 | E13: =WBS!J13 | F13: =CPM!E10 | G13: =CPM!F10 | H13: =IF(AND(1>$F13,1<=$G13),$E13/($G13-$F13),0) | I13: =IF(AND(2>$F13,2<=$G13),$E13/($G13-$F13),0) | J13: =IF(AND(3>$F13,3<=$G13),$E13/($G13-$F13),0) | K13: =IF(AND(4>$F13,4<=$G13),$E13/($G13-$F13),0) | L13: =IF(AND(5>$F13,5<=$G13),$E13/($G13-$F13),0) | M13: =IF(AND(6>$F13,6<=$G13),$E13/($G13-$F13),0) | N13: =IF(AND(7>$F13,7<=$G13),$E13/($G13-$F13),0) | O13: =IF(AND(8>$F13,8<=$G13),$E13/($G13-$F13),0) | P13: =IF(AND(9>$F13,9<=$G13),$E13/($G13-$F13),0) | Q13: =IF(AND(10>$F13,10<=$G13),$E13/($G13-$F13),0) | R13: =IF(AND(11>$F13,11<=$G13),$E13/($G13-$F13),0) | S13: =IF(AND(12>$F13,12<=$G13),$E13/($G13-$F13),0) | T13: =IF(AND(13>$F13,13<=$G13),$E13/($G13-$F13),0) | U13: =IF(AND(14>$F13,14<=$G13),$E13/($G13-$F13),0) | V13: =IF(AND(15>$F13,15<=$G13),$E13/($G13-$F13),0) | W13: =IF(AND(16>$F13,16<=$G13),$E13/($G13-$F13),0)
A14: =WBS!A14 | B14: =WBS!B14 | C14: =WBS!D14 | D14: =WBS!E14 | E14: =WBS!J14 | F14: =CPM!E10 | G14: =CPM!F10 | H14: =IF(AND(1>$F14,1<=$G14),$E14/($G14-$F14),0) | I14: =IF(AND(2>$F14,2<=$G14),$E14/($G14-$F14),0) | J14: =IF(AND(3>$F14,3<=$G14),$E14/($G14-$F14),0) | K14: =IF(AND(4>$F14,4<=$G14),$E14/($G14-$F14),0) | L14: =IF(AND(5>$F14,5<=$G14),$E14/($G14-$F14),0) | M14: =IF(AND(6>$F14,6<=$G14),$E14/($G14-$F14),0) | N14: =IF(AND(7>$F14,7<=$G14),$E14/($G14-$F14),0) | O14: =IF(AND(8>$F14,8<=$G14),$E14/($G14-$F14),0) | P14: =IF(AND(9>$F14,9<=$G14),$E14/($G14-$F14),0) | Q14: =IF(AND(10>$F14,10<=$G14),$E14/($G14-$F14),0) | R14: =IF(AND(11>$F14,11<=$G14),$E14/($G14-$F14),0) | S14: =IF(AND(12>$F14,12<=$G14),$E14/($G14-$F14),0) | T14: =IF(AND(13>$F14,13<=$G14),$E14/($G14-$F14),0) | U14: =IF(AND(14>$F14,14<=$G14),$E14/($G14-$F14),0) | V14: =IF(AND(15>$F14,15<=$G14),$E14/($G14-$F14),0) | W14: =IF(AND(16>$F14,16<=$G14),$E14/($G14-$F14),0)
A15: =WBS!A15 | B15: =WBS!B15 | C15: =WBS!D15 | D15: =WBS!E15 | E15: =WBS!J15 | F15: =CPM!E11 | G15: =CPM!F11 | H15: =IF(AND(1>$F15,1<=$G15),$E15/($G15-$F15),0) | I15: =IF(AND(2>$F15,2<=$G15),$E15/($G15-$F15),0) | J15: =IF(AND(3>$F15,3<=$G15),$E15/($G15-$F15),0) | K15: =IF(AND(4>$F15,4<=$G15),$E15/($G15-$F15),0) | L15: =IF(AND(5>$F15,5<=$G15),$E15/($G15-$F15),0) | M15: =IF(AND(6>$F15,6<=$G15),$E15/($G15-$F15),0) | N15: =IF(AND(7>$F15,7<=$G15),$E15/($G15-$F15),0) | O15: =IF(AND(8>$F15,8<=$G15),$E15/($G15-$F15),0) | P15: =IF(AND(9>$F15,9<=$G15),$E15/($G15-$F15),0) | Q15: =IF(AND(10>$F15,10<=$G15),$E15/($G15-$F15),0) | R15: =IF(AND(11>$F15,11<=$G15),$E15/($G15-$F15),0) | S15: =IF(AND(12>$F15,12<=$G15),$E15/($G15-$F15),0) | T15: =IF(AND(13>$F15,13<=$G15),$E15/($G15-$F15),0) | U15: =IF(AND(14>$F15,14<=$G15),$E15/($G15-$F15),0) | V15: =IF(AND(15>$F15,15<=$G15),$E15/($G15-$F15),0) | W15: =IF(AND(16>$F15,16<=$G15),$E15/($G15-$F15),0)
A16: =WBS!A16 | B16: =WBS!B16 | C16: =WBS!D16 | D16: =WBS!E16 | E16: =WBS!J16 | F16: =CPM!E12 | G16: =CPM!F12 | H16: =IF(AND(1>$F16,1<=$G16),$E16/($G16-$F16),0) | I16: =IF(AND(2>$F16,2<=$G16),$E16/($G16-$F16),0) | J16: =IF(AND(3>$F16,3<=$G16),$E16/($G16-$F16),0) | K16: =IF(AND(4>$F16,4<=$G16),$E16/($G16-$F16),0) | L16: =IF(AND(5>$F16,5<=$G16),$E16/($G16-$F16),0) | M16: =IF(AND(6>$F16,6<=$G16),$E16/($G16-$F16),0) | N16: =IF(AND(7>$F16,7<=$G16),$E16/($G16-$F16),0) | O16: =IF(AND(8>$F16,8<=$G16),$E16/($G16-$F16),0) | P16: =IF(AND(9>$F16,9<=$G16),$E16/($G16-$F16),0) | Q16: =IF(AND(10>$F16,10<=$G16),$E16/($G16-$F16),0) | R16: =IF(AND(11>$F16,11<=$G16),$E16/($G16-$F16),0) | S16: =IF(AND(12>$F16,12<=$G16),$E16/($G16-$F16),0) | T16: =IF(AND(13>$F16,13<=$G16),$E16/($G16-$F16),0) | U16: =IF(AND(14>$F16,14<=$G16),$E16/($G16-$F16),0) | V16: =IF(AND(15>$F16,15<=$G16),$E16/($G16-$F16),0) | W16: =IF(AND(16>$F16,16<=$G16),$E16/($G16-$F16),0)
A17: =WBS!A17 | B17: =WBS!B17 | C17: =WBS!D17 | D17: =WBS!E17 | E17: =WBS!J17 | F17: =CPM!E14 | G17: =CPM!F14 | H17: =IF(AND(1>$F17,1<=$G17),$E17/($G17-$F17),0) | I17: =IF(AND(2>$F17,2<=$G17),$E17/($G17-$F17),0) | J17: =IF(AND(3>$F17,3<=$G17),$E17/($G17-$F17),0) | K17: =IF(AND(4>$F17,4<=$G17),$E17/($G17-$F17),0) | L17: =IF(AND(5>$F17,5<=$G17),$E17/($G17-$F17),0) | M17: =IF(AND(6>$F17,6<=$G17),$E17/($G17-$F17),0) | N17: =IF(AND(7>$F17,7<=$G17),$E17/($G17-$F17),0) | O17: =IF(AND(8>$F17,8<=$G17),$E17/($G17-$F17),0) | P17: =IF(AND(9>$F17,9<=$G17),$E17/($G17-$F17),0) | Q17: =IF(AND(10>$F17,10<=$G17),$E17/($G17-$F17),0) | R17: =IF(AND(11>$F17,11<=$G17),$E17/($G17-$F17),0) | S17: =IF(AND(12>$F17,12<=$G17),$E17/($G17-$F17),0) | T17: =IF(AND(13>$F17,13<=$G17),$E17/($G17-$F17),0) | U17: =IF(AND(14>$F17,14<=$G17),$E17/($G17-$F17),0) | V17: =IF(AND(15>$F17,15<=$G17),$E17/($G17-$F17),0) | W17: =IF(AND(16>$F17,16<=$G17),$E17/($G17-$F17),0)
A18: =WBS!A18 | B18: =WBS!B18 | C18: =WBS!D18 | D18: =WBS!E18 | E18: =WBS!J18 | F18: =CPM!E12 | G18: =CPM!F12 | H18: =IF(AND(1>$F18,1<=$G18),$E18/($G18-$F18),0) | I18: =IF(AND(2>$F18,2<=$G18),$E18/($G18-$F18),0) | J18: =IF(AND(3>$F18,3<=$G18),$E18/($G18-$F18),0) | K18: =IF(AND(4>$F18,4<=$G18),$E18/($G18-$F18),0) | L18: =IF(AND(5>$F18,5<=$G18),$E18/($G18-$F18),0) | M18: =IF(AND(6>$F18,6<=$G18),$E18/($G18-$F18),0) | N18: =IF(AND(7>$F18,7<=$G18),$E18/($G18-$F18),0) | O18: =IF(AND(8>$F18,8<=$G18),$E18/($G18-$F18),0) | P18: =IF(AND(9>$F18,9<=$G18),$E18/($G18-$F18),0) | Q18: =IF(AND(10>$F18,10<=$G18),$E18/($G18-$F18),0) | R18: =IF(AND(11>$F18,11<=$G18),$E18/($G18-$F18),0) | S18: =IF(AND(12>$F18,12<=$G18),$E18/($G18-$F18),0) | T18: =IF(AND(13>$F18,13<=$G18),$E18/($G18-$F18),0) | U18: =IF(AND(14>$F18,14<=$G18),$E18/($G18-$F18),0) | V18: =IF(AND(15>$F18,15<=$G18),$E18/($G18-$F18),0) | W18: =IF(AND(16>$F18,16<=$G18),$E18/($G18-$F18),0)
A19: =WBS!A19 | B19: =WBS!B19 | C19: =WBS!D19 | D19: =WBS!E19 | E19: =WBS!J19 | F19: =CPM!E12 | G19: =CPM!F12 | H19: =IF(AND(1>$F19,1<=$G19),$E19/($G19-$F19),0) | I19: =IF(AND(2>$F19,2<=$G19),$E19/($G19-$F19),0) | J19: =IF(AND(3>$F19,3<=$G19),$E19/($G19-$F19),0) | K19: =IF(AND(4>$F19,4<=$G19),$E19/($G19-$F19),0) | L19: =IF(AND(5>$F19,5<=$G19),$E19/($G19-$F19),0) | M19: =IF(AND(6>$F19,6<=$G19),$E19/($G19-$F19),0) | N19: =IF(AND(7>$F19,7<=$G19),$E19/($G19-$F19),0) | O19: =IF(AND(8>$F19,8<=$G19),$E19/($G19-$F19),0) | P19: =IF(AND(9>$F19,9<=$G19),$E19/($G19-$F19),0) | Q19: =IF(AND(10>$F19,10<=$G19),$E19/($G19-$F19),0) | R19: =IF(AND(11>$F19,11<=$G19),$E19/($G19-$F19),0) | S19: =IF(AND(12>$F19,12<=$G19),$E19/($G19-$F19),0) | T19: =IF(AND(13>$F19,13<=$G19),$E19/($G19-$F19),0) | U19: =IF(AND(14>$F19,14<=$G19),$E19/($G19-$F19),0) | V19: =IF(AND(15>$F19,15<=$G19),$E19/($G19-$F19),0) | W19: =IF(AND(16>$F19,16<=$G19),$E19/($G19-$F19),0)
A20: =WBS!A20 | B20: =WBS!B20 | C20: =WBS!D20 | D20: =WBS!E20 | E20: =WBS!J20 | F20: =CPM!E14 | G20: =CPM!F14 | H20: =IF(AND(1>$F20,1<=$G20),$E20/($G20-$F20),0) | I20: =IF(AND(2>$F20,2<=$G20),$E20/($G20-$F20),0) | J20: =IF(AND(3>$F20,3<=$G20),$E20/($G20-$F20),0) | K20: =IF(AND(4>$F20,4<=$G20),$E20/($G20-$F20),0) | L20: =IF(AND(5>$F20,5<=$G20),$E20/($G20-$F20),0) | M20: =IF(AND(6>$F20,6<=$G20),$E20/($G20-$F20),0) | N20: =IF(AND(7>$F20,7<=$G20),$E20/($G20-$F20),0) | O20: =IF(AND(8>$F20,8<=$G20),$E20/($G20-$F20),0) | P20: =IF(AND(9>$F20,9<=$G20),$E20/($G20-$F20),0) | Q20: =IF(AND(10>$F20,10<=$G20),$E20/($G20-$F20),0) | R20: =IF(AND(11>$F20,11<=$G20),$E20/($G20-$F20),0) | S20: =IF(AND(12>$F20,12<=$G20),$E20/($G20-$F20),0) | T20: =IF(AND(13>$F20,13<=$G20),$E20/($G20-$F20),0) | U20: =IF(AND(14>$F20,14<=$G20),$E20/($G20-$F20),0) | V20: =IF(AND(15>$F20,15<=$G20),$E20/($G20-$F20),0) | W20: =IF(AND(16>$F20,16<=$G20),$E20/($G20-$F20),0)
A21: =WBS!A21 | B21: =WBS!B21 | C21: =WBS!D21 | D21: =WBS!E21 | E21: =WBS!J21 | F21: =CPM!E13 | G21: =CPM!F13 | H21: =IF(AND(1>$F21,1<=$G21),$E21/($G21-$F21),0) | I21: =IF(AND(2>$F21,2<=$G21),$E21/($G21-$F21),0) | J21: =IF(AND(3>$F21,3<=$G21),$E21/($G21-$F21),0) | K21: =IF(AND(4>$F21,4<=$G21),$E21/($G21-$F21),0) | L21: =IF(AND(5>$F21,5<=$G21),$E21/($G21-$F21),0) | M21: =IF(AND(6>$F21,6<=$G21),$E21/($G21-$F21),0) | N21: =IF(AND(7>$F21,7<=$G21),$E21/($G21-$F21),0) | O21: =IF(AND(8>$F21,8<=$G21),$E21/($G21-$F21),0) | P21: =IF(AND(9>$F21,9<=$G21),$E21/($G21-$F21),0) | Q21: =IF(AND(10>$F21,10<=$G21),$E21/($G21-$F21),0) | R21: =IF(AND(11>$F21,11<=$G21),$E21/($G21-$F21),0) | S21: =IF(AND(12>$F21,12<=$G21),$E21/($G21-$F21),0) | T21: =IF(AND(13>$F21,13<=$G21),$E21/($G21-$F21),0) | U21: =IF(AND(14>$F21,14<=$G21),$E21/($G21-$F21),0) | V21: =IF(AND(15>$F21,15<=$G21),$E21/($G21-$F21),0) | W21: =IF(AND(16>$F21,16<=$G21),$E21/($G21-$F21),0)
A22: =WBS!A22 | B22: =WBS!B22 | C22: =WBS!D22 | D22: =WBS!E22 | E22: =WBS!J22 | F22: =CPM!E13 | G22: =CPM!F13 | H22: =IF(AND(1>$F22,1<=$G22),$E22/($G22-$F22),0) | I22: =IF(AND(2>$F22,2<=$G22),$E22/($G22-$F22),0) | J22: =IF(AND(3>$F22,3<=$G22),$E22/($G22-$F22),0) | K22: =IF(AND(4>$F22,4<=$G22),$E22/($G22-$F22),0) | L22: =IF(AND(5>$F22,5<=$G22),$E22/($G22-$F22),0) | M22: =IF(AND(6>$F22,6<=$G22),$E22/($G22-$F22),0) | N22: =IF(AND(7>$F22,7<=$G22),$E22/($G22-$F22),0) | O22: =IF(AND(8>$F22,8<=$G22),$E22/($G22-$F22),0) | P22: =IF(AND(9>$F22,9<=$G22),$E22/($G22-$F22),0) | Q22: =IF(AND(10>$F22,10<=$G22),$E22/($G22-$F22),0) | R22: =IF(AND(11>$F22,11<=$G22),$E22/($G22-$F22),0) | S22: =IF(AND(12>$F22,12<=$G22),$E22/($G22-$F22),0) | T22: =IF(AND(13>$F22,13<=$G22),$E22/($G22-$F22),0) | U22: =IF(AND(14>$F22,14<=$G22),$E22/($G22-$F22),0) | V22: =IF(AND(15>$F22,15<=$G22),$E22/($G22-$F22),0) | W22: =IF(AND(16>$F22,16<=$G22),$E22/($G22-$F22),0)
A23: =WBS!A23 | B23: =WBS!B23 | C23: =WBS!D23 | D23: =WBS!E23 | E23: =WBS!J23 | F23: =CPM!E15 | G23: =CPM!F15 | H23: =IF(AND(1>$F23,1<=$G23),$E23/($G23-$F23),0) | I23: =IF(AND(2>$F23,2<=$G23),$E23/($G23-$F23),0) | J23: =IF(AND(3>$F23,3<=$G23),$E23/($G23-$F23),0) | K23: =IF(AND(4>$F23,4<=$G23),$E23/($G23-$F23),0) | L23: =IF(AND(5>$F23,5<=$G23),$E23/($G23-$F23),0) | M23: =IF(AND(6>$F23,6<=$G23),$E23/($G23-$F23),0) | N23: =IF(AND(7>$F23,7<=$G23),$E23/($G23-$F23),0) | O23: =IF(AND(8>$F23,8<=$G23),$E23/($G23-$F23),0) | P23: =IF(AND(9>$F23,9<=$G23),$E23/($G23-$F23),0) | Q23: =IF(AND(10>$F23,10<=$G23),$E23/($G23-$F23),0) | R23: =IF(AND(11>$F23,11<=$G23),$E23/($G23-$F23),0) | S23: =IF(AND(12>$F23,12<=$G23),$E23/($G23-$F23),0) | T23: =IF(AND(13>$F23,13<=$G23),$E23/($G23-$F23),0) | U23: =IF(AND(14>$F23,14<=$G23),$E23/($G23-$F23),0) | V23: =IF(AND(15>$F23,15<=$G23),$E23/($G23-$F23),0) | W23: =IF(AND(16>$F23,16<=$G23),$E23/($G23-$F23),0)
A24: =WBS!A24 | B24: =WBS!B24 | C24: =WBS!D24 | D24: =WBS!E24 | E24: =WBS!J24 | F24: =CPM!E13 | G24: =CPM!F13 | H24: =IF(AND(1>$F24,1<=$G24),$E24/($G24-$F24),0) | I24: =IF(AND(2>$F24,2<=$G24),$E24/($G24-$F24),0) | J24: =IF(AND(3>$F24,3<=$G24),$E24/($G24-$F24),0) | K24: =IF(AND(4>$F24,4<=$G24),$E24/($G24-$F24),0) | L24: =IF(AND(5>$F24,5<=$G24),$E24/($G24-$F24),0) | M24: =IF(AND(6>$F24,6<=$G24),$E24/($G24-$F24),0) | N24: =IF(AND(7>$F24,7<=$G24),$E24/($G24-$F24),0) | O24: =IF(AND(8>$F24,8<=$G24),$E24/($G24-$F24),0) | P24: =IF(AND(9>$F24,9<=$G24),$E24/($G24-$F24),0) | Q24: =IF(AND(10>$F24,10<=$G24),$E24/($G24-$F24),0) | R24: =IF(AND(11>$F24,11<=$G24),$E24/($G24-$F24),0) | S24: =IF(AND(12>$F24,12<=$G24),$E24/($G24-$F24),0) | T24: =IF(AND(13>$F24,13<=$G24),$E24/($G24-$F24),0) | U24: =IF(AND(14>$F24,14<=$G24),$E24/($G24-$F24),0) | V24: =IF(AND(15>$F24,15<=$G24),$E24/($G24-$F24),0) | W24: =IF(AND(16>$F24,16<=$G24),$E24/($G24-$F24),0)
A25: =WBS!A25 | B25: =WBS!B25 | C25: =WBS!D25 | D25: =WBS!E25 | E25: =WBS!J25 | F25: =CPM!E14 | G25: =CPM!F14 | H25: =IF(AND(1>$F25,1<=$G25),$E25/($G25-$F25),0) | I25: =IF(AND(2>$F25,2<=$G25),$E25/($G25-$F25),0) | J25: =IF(AND(3>$F25,3<=$G25),$E25/($G25-$F25),0) | K25: =IF(AND(4>$F25,4<=$G25),$E25/($G25-$F25),0) | L25: =IF(AND(5>$F25,5<=$G25),$E25/($G25-$F25),0) | M25: =IF(AND(6>$F25,6<=$G25),$E25/($G25-$F25),0) | N25: =IF(AND(7>$F25,7<=$G25),$E25/($G25-$F25),0) | O25: =IF(AND(8>$F25,8<=$G25),$E25/($G25-$F25),0) | P25: =IF(AND(9>$F25,9<=$G25),$E25/($G25-$F25),0) | Q25: =IF(AND(10>$F25,10<=$G25),$E25/($G25-$F25),0) | R25: =IF(AND(11>$F25,11<=$G25),$E25/($G25-$F25),0) | S25: =IF(AND(12>$F25,12<=$G25),$E25/($G25-$F25),0) | T25: =IF(AND(13>$F25,13<=$G25),$E25/($G25-$F25),0) | U25: =IF(AND(14>$F25,14<=$G25),$E25/($G25-$F25),0) | V25: =IF(AND(15>$F25,15<=$G25),$E25/($G25-$F25),0) | W25: =IF(AND(16>$F25,16<=$G25),$E25/($G25-$F25),0)
A26: =WBS!A26 | B26: =WBS!B26 | C26: =WBS!D26 | D26: =WBS!E26 | E26: =WBS!J26 | F26: =CPM!E13 | G26: =CPM!F13 | H26: =IF(AND(1>$F26,1<=$G26),$E26/($G26-$F26),0) | I26: =IF(AND(2>$F26,2<=$G26),$E26/($G26-$F26),0) | J26: =IF(AND(3>$F26,3<=$G26),$E26/($G26-$F26),0) | K26: =IF(AND(4>$F26,4<=$G26),$E26/($G26-$F26),0) | L26: =IF(AND(5>$F26,5<=$G26),$E26/($G26-$F26),0) | M26: =IF(AND(6>$F26,6<=$G26),$E26/($G26-$F26),0) | N26: =IF(AND(7>$F26,7<=$G26),$E26/($G26-$F26),0) | O26: =IF(AND(8>$F26,8<=$G26),$E26/($G26-$F26),0) | P26: =IF(AND(9>$F26,9<=$G26),$E26/($G26-$F26),0) | Q26: =IF(AND(10>$F26,10<=$G26),$E26/($G26-$F26),0) | R26: =IF(AND(11>$F26,11<=$G26),$E26/($G26-$F26),0) | S26: =IF(AND(12>$F26,12<=$G26),$E26/($G26-$F26),0) | T26: =IF(AND(13>$F26,13<=$G26),$E26/($G26-$F26),0) | U26: =IF(AND(14>$F26,14<=$G26),$E26/($G26-$F26),0) | V26: =IF(AND(15>$F26,15<=$G26),$E26/($G26-$F26),0) | W26: =IF(AND(16>$F26,16<=$G26),$E26/($G26-$F26),0)
A27: =WBS!A27 | B27: =WBS!B27 | C27: =WBS!D27 | D27: =WBS!E27 | E27: =WBS!J27 | F27: =CPM!E15 | G27: =CPM!F15 | H27: =IF(AND(1>$F27,1<=$G27),$E27/($G27-$F27),0) | I27: =IF(AND(2>$F27,2<=$G27),$E27/($G27-$F27),0) | J27: =IF(AND(3>$F27,3<=$G27),$E27/($G27-$F27),0) | K27: =IF(AND(4>$F27,4<=$G27),$E27/($G27-$F27),0) | L27: =IF(AND(5>$F27,5<=$G27),$E27/($G27-$F27),0) | M27: =IF(AND(6>$F27,6<=$G27),$E27/($G27-$F27),0) | N27: =IF(AND(7>$F27,7<=$G27),$E27/($G27-$F27),0) | O27: =IF(AND(8>$F27,8<=$G27),$E27/($G27-$F27),0) | P27: =IF(AND(9>$F27,9<=$G27),$E27/($G27-$F27),0) | Q27: =IF(AND(10>$F27,10<=$G27),$E27/($G27-$F27),0) | R27: =IF(AND(11>$F27,11<=$G27),$E27/($G27-$F27),0) | S27: =IF(AND(12>$F27,12<=$G27),$E27/($G27-$F27),0) | T27: =IF(AND(13>$F27,13<=$G27),$E27/($G27-$F27),0) | U27: =IF(AND(14>$F27,14<=$G27),$E27/($G27-$F27),0) | V27: =IF(AND(15>$F27,15<=$G27),$E27/($G27-$F27),0) | W27: =IF(AND(16>$F27,16<=$G27),$E27/($G27-$F27),0)
A28: =WBS!A28 | B28: =WBS!B28 | C28: =WBS!D28 | D28: =WBS!E28 | E28: =WBS!J28 | F28: =CPM!E16 | G28: =CPM!F16 | H28: =IF(AND(1>$F28,1<=$G28),$E28/($G28-$F28),0) | I28: =IF(AND(2>$F28,2<=$G28),$E28/($G28-$F28),0) | J28: =IF(AND(3>$F28,3<=$G28),$E28/($G28-$F28),0) | K28: =IF(AND(4>$F28,4<=$G28),$E28/($G28-$F28),0) | L28: =IF(AND(5>$F28,5<=$G28),$E28/($G28-$F28),0) | M28: =IF(AND(6>$F28,6<=$G28),$E28/($G28-$F28),0) | N28: =IF(AND(7>$F28,7<=$G28),$E28/($G28-$F28),0) | O28: =IF(AND(8>$F28,8<=$G28),$E28/($G28-$F28),0) | P28: =IF(AND(9>$F28,9<=$G28),$E28/($G28-$F28),0) | Q28: =IF(AND(10>$F28,10<=$G28),$E28/($G28-$F28),0) | R28: =IF(AND(11>$F28,11<=$G28),$E28/($G28-$F28),0) | S28: =IF(AND(12>$F28,12<=$G28),$E28/($G28-$F28),0) | T28: =IF(AND(13>$F28,13<=$G28),$E28/($G28-$F28),0) | U28: =IF(AND(14>$F28,14<=$G28),$E28/($G28-$F28),0) | V28: =IF(AND(15>$F28,15<=$G28),$E28/($G28-$F28),0) | W28: =IF(AND(16>$F28,16<=$G28),$E28/($G28-$F28),0)
A29: =WBS!A29 | B29: =WBS!B29 | C29: =WBS!D29 | D29: =WBS!E29 | E29: =WBS!J29 | F29: =CPM!E16 | G29: =CPM!F16 | H29: =IF(AND(1>$F29,1<=$G29),$E29/($G29-$F29),0) | I29: =IF(AND(2>$F29,2<=$G29),$E29/($G29-$F29),0) | J29: =IF(AND(3>$F29,3<=$G29),$E29/($G29-$F29),0) | K29: =IF(AND(4>$F29,4<=$G29),$E29/($G29-$F29),0) | L29: =IF(AND(5>$F29,5<=$G29),$E29/($G29-$F29),0) | M29: =IF(AND(6>$F29,6<=$G29),$E29/($G29-$F29),0) | N29: =IF(AND(7>$F29,7<=$G29),$E29/($G29-$F29),0) | O29: =IF(AND(8>$F29,8<=$G29),$E29/($G29-$F29),0) | P29: =IF(AND(9>$F29,9<=$G29),$E29/($G29-$F29),0) | Q29: =IF(AND(10>$F29,10<=$G29),$E29/($G29-$F29),0) | R29: =IF(AND(11>$F29,11<=$G29),$E29/($G29-$F29),0) | S29: =IF(AND(12>$F29,12<=$G29),$E29/($G29-$F29),0) | T29: =IF(AND(13>$F29,13<=$G29),$E29/($G29-$F29),0) | U29: =IF(AND(14>$F29,14<=$G29),$E29/($G29-$F29),0) | V29: =IF(AND(15>$F29,15<=$G29),$E29/($G29-$F29),0) | W29: =IF(AND(16>$F29,16<=$G29),$E29/($G29-$F29),0)
A30: =WBS!A30 | B30: =WBS!B30 | C30: =WBS!D30 | D30: =WBS!E30 | E30: =WBS!J30 | F30: =CPM!E17 | G30: =CPM!F17 | H30: =IF(AND(1>$F30,1<=$G30),$E30/($G30-$F30),0) | I30: =IF(AND(2>$F30,2<=$G30),$E30/($G30-$F30),0) | J30: =IF(AND(3>$F30,3<=$G30),$E30/($G30-$F30),0) | K30: =IF(AND(4>$F30,4<=$G30),$E30/($G30-$F30),0) | L30: =IF(AND(5>$F30,5<=$G30),$E30/($G30-$F30),0) | M30: =IF(AND(6>$F30,6<=$G30),$E30/($G30-$F30),0) | N30: =IF(AND(7>$F30,7<=$G30),$E30/($G30-$F30),0) | O30: =IF(AND(8>$F30,8<=$G30),$E30/($G30-$F30),0) | P30: =IF(AND(9>$F30,9<=$G30),$E30/($G30-$F30),0) | Q30: =IF(AND(10>$F30,10<=$G30),$E30/($G30-$F30),0) | R30: =IF(AND(11>$F30,11<=$G30),$E30/($G30-$F30),0) | S30: =IF(AND(12>$F30,12<=$G30),$E30/($G30-$F30),0) | T30: =IF(AND(13>$F30,13<=$G30),$E30/($G30-$F30),0) | U30: =IF(AND(14>$F30,14<=$G30),$E30/($G30-$F30),0) | V30: =IF(AND(15>$F30,15<=$G30),$E30/($G30-$F30),0) | W30: =IF(AND(16>$F30,16<=$G30),$E30/($G30-$F30),0)
A31: =WBS!A31 | B31: =WBS!B31 | C31: =WBS!D31 | D31: =WBS!E31 | E31: =WBS!J31 | F31: =CPM!E17 | G31: =CPM!F17 | H31: =IF(AND(1>$F31,1<=$G31),$E31/($G31-$F31),0) | I31: =IF(AND(2>$F31,2<=$G31),$E31/($G31-$F31),0) | J31: =IF(AND(3>$F31,3<=$G31),$E31/($G31-$F31),0) | K31: =IF(AND(4>$F31,4<=$G31),$E31/($G31-$F31),0) | L31: =IF(AND(5>$F31,5<=$G31),$E31/($G31-$F31),0) | M31: =IF(AND(6>$F31,6<=$G31),$E31/($G31-$F31),0) | N31: =IF(AND(7>$F31,7<=$G31),$E31/($G31-$F31),0) | O31: =IF(AND(8>$F31,8<=$G31),$E31/($G31-$F31),0) | P31: =IF(AND(9>$F31,9<=$G31),$E31/($G31-$F31),0) | Q31: =IF(AND(10>$F31,10<=$G31),$E31/($G31-$F31),0) | R31: =IF(AND(11>$F31,11<=$G31),$E31/($G31-$F31),0) | S31: =IF(AND(12>$F31,12<=$G31),$E31/($G31-$F31),0) | T31: =IF(AND(13>$F31,13<=$G31),$E31/($G31-$F31),0) | U31: =IF(AND(14>$F31,14<=$G31),$E31/($G31-$F31),0) | V31: =IF(AND(15>$F31,15<=$G31),$E31/($G31-$F31),0) | W31: =IF(AND(16>$F31,16<=$G31),$E31/($G31-$F31),0)
A32: =WBS!A32 | B32: =WBS!B32 | C32: =WBS!D32 | D32: =WBS!E32 | E32: =WBS!J32 | F32: =CPM!E17 | G32: =CPM!F17 | H32: =IF(AND(1>$F32,1<=$G32),$E32/($G32-$F32),0) | I32: =IF(AND(2>$F32,2<=$G32),$E32/($G32-$F32),0) | J32: =IF(AND(3>$F32,3<=$G32),$E32/($G32-$F32),0) | K32: =IF(AND(4>$F32,4<=$G32),$E32/($G32-$F32),0) | L32: =IF(AND(5>$F32,5<=$G32),$E32/($G32-$F32),0) | M32: =IF(AND(6>$F32,6<=$G32),$E32/($G32-$F32),0) | N32: =IF(AND(7>$F32,7<=$G32),$E32/($G32-$F32),0) | O32: =IF(AND(8>$F32,8<=$G32),$E32/($G32-$F32),0) | P32: =IF(AND(9>$F32,9<=$G32),$E32/($G32-$F32),0) | Q32: =IF(AND(10>$F32,10<=$G32),$E32/($G32-$F32),0) | R32: =IF(AND(11>$F32,11<=$G32),$E32/($G32-$F32),0) | S32: =IF(AND(12>$F32,12<=$G32),$E32/($G32-$F32),0) | T32: =IF(AND(13>$F32,13<=$G32),$E32/($G32-$F32),0) | U32: =IF(AND(14>$F32,14<=$G32),$E32/($G32-$F32),0) | V32: =IF(AND(15>$F32,15<=$G32),$E32/($G32-$F32),0) | W32: =IF(AND(16>$F32,16<=$G32),$E32/($G32-$F32),0)
A33: =WBS!A33 | B33: =WBS!B33 | C33: =WBS!D33 | D33: =WBS!E33 | E33: =WBS!J33 | F33: =CPM!E18 | G33: =CPM!F18 | H33: =IF(AND(1>$F33,1<=$G33),$E33/($G33-$F33),0) | I33: =IF(AND(2>$F33,2<=$G33),$E33/($G33-$F33),0) | J33: =IF(AND(3>$F33,3<=$G33),$E33/($G33-$F33),0) | K33: =IF(AND(4>$F33,4<=$G33),$E33/($G33-$F33),0) | L33: =IF(AND(5>$F33,5<=$G33),$E33/($G33-$F33),0) | M33: =IF(AND(6>$F33,6<=$G33),$E33/($G33-$F33),0) | N33: =IF(AND(7>$F33,7<=$G33),$E33/($G33-$F33),0) | O33: =IF(AND(8>$F33,8<=$G33),$E33/($G33-$F33),0) | P33: =IF(AND(9>$F33,9<=$G33),$E33/($G33-$F33),0) | Q33: =IF(AND(10>$F33,10<=$G33),$E33/($G33-$F33),0) | R33: =IF(AND(11>$F33,11<=$G33),$E33/($G33-$F33),0) | S33: =IF(AND(12>$F33,12<=$G33),$E33/($G33-$F33),0) | T33: =IF(AND(13>$F33,13<=$G33),$E33/($G33-$F33),0) | U33: =IF(AND(14>$F33,14<=$G33),$E33/($G33-$F33),0) | V33: =IF(AND(15>$F33,15<=$G33),$E33/($G33-$F33),0) | W33: =IF(AND(16>$F33,16<=$G33),$E33/($G33-$F33),0)
A34: =WBS!A34 | B34: =WBS!B34 | C34: =WBS!D34 | D34: =WBS!E34 | E34: =WBS!J34 | F34: =CPM!E18 | G34: =CPM!F18 | H34: =IF(AND(1>$F34,1<=$G34),$E34/($G34-$F34),0) | I34: =IF(AND(2>$F34,2<=$G34),$E34/($G34-$F34),0) | J34: =IF(AND(3>$F34,3<=$G34),$E34/($G34-$F34),0) | K34: =IF(AND(4>$F34,4<=$G34),$E34/($G34-$F34),0) | L34: =IF(AND(5>$F34,5<=$G34),$E34/($G34-$F34),0) | M34: =IF(AND(6>$F34,6<=$G34),$E34/($G34-$F34),0) | N34: =IF(AND(7>$F34,7<=$G34),$E34/($G34-$F34),0) | O34: =IF(AND(8>$F34,8<=$G34),$E34/($G34-$F34),0) | P34: =IF(AND(9>$F34,9<=$G34),$E34/($G34-$F34),0) | Q34: =IF(AND(10>$F34,10<=$G34),$E34/($G34-$F34),0) | R34: =IF(AND(11>$F34,11<=$G34),$E34/($G34-$F34),0) | S34: =IF(AND(12>$F34,12<=$G34),$E34/($G34-$F34),0) | T34: =IF(AND(13>$F34,13<=$G34),$E34/($G34-$F34),0) | U34: =IF(AND(14>$F34,14<=$G34),$E34/($G34-$F34),0) | V34: =IF(AND(15>$F34,15<=$G34),$E34/($G34-$F34),0) | W34: =IF(AND(16>$F34,16<=$G34),$E34/($G34-$F34),0)
A35: =WBS!A35 | B35: =WBS!B35 | C35: =WBS!D35 | D35: =WBS!E35 | E35: =WBS!J35 | F35: =CPM!E18 | G35: =CPM!F18 | H35: =IF(AND(1>$F35,1<=$G35),$E35/($G35-$F35),0) | I35: =IF(AND(2>$F35,2<=$G35),$E35/($G35-$F35),0) | J35: =IF(AND(3>$F35,3<=$G35),$E35/($G35-$F35),0) | K35: =IF(AND(4>$F35,4<=$G35),$E35/($G35-$F35),0) | L35: =IF(AND(5>$F35,5<=$G35),$E35/($G35-$F35),0) | M35: =IF(AND(6>$F35,6<=$G35),$E35/($G35-$F35),0) | N35: =IF(AND(7>$F35,7<=$G35),$E35/($G35-$F35),0) | O35: =IF(AND(8>$F35,8<=$G35),$E35/($G35-$F35),0) | P35: =IF(AND(9>$F35,9<=$G35),$E35/($G35-$F35),0) | Q35: =IF(AND(10>$F35,10<=$G35),$E35/($G35-$F35),0) | R35: =IF(AND(11>$F35,11<=$G35),$E35/($G35-$F35),0) | S35: =IF(AND(12>$F35,12<=$G35),$E35/($G35-$F35),0) | T35: =IF(AND(13>$F35,13<=$G35),$E35/($G35-$F35),0) | U35: =IF(AND(14>$F35,14<=$G35),$E35/($G35-$F35),0) | V35: =IF(AND(15>$F35,15<=$G35),$E35/($G35-$F35),0) | W35: =IF(AND(16>$F35,16<=$G35),$E35/($G35-$F35),0)
A36: =WBS!A36 | B36: =WBS!B36 | C36: =WBS!D36 | D36: =WBS!E36 | E36: =WBS!J36 | F36: =CPM!E19 | G36: =CPM!F19 | H36: =IF(AND(1>$F36,1<=$G36),$E36/($G36-$F36),0) | I36: =IF(AND(2>$F36,2<=$G36),$E36/($G36-$F36),0) | J36: =IF(AND(3>$F36,3<=$G36),$E36/($G36-$F36),0) | K36: =IF(AND(4>$F36,4<=$G36),$E36/($G36-$F36),0) | L36: =IF(AND(5>$F36,5<=$G36),$E36/($G36-$F36),0) | M36: =IF(AND(6>$F36,6<=$G36),$E36/($G36-$F36),0) | N36: =IF(AND(7>$F36,7<=$G36),$E36/($G36-$F36),0) | O36: =IF(AND(8>$F36,8<=$G36),$E36/($G36-$F36),0) | P36: =IF(AND(9>$F36,9<=$G36),$E36/($G36-$F36),0) | Q36: =IF(AND(10>$F36,10<=$G36),$E36/($G36-$F36),0) | R36: =IF(AND(11>$F36,11<=$G36),$E36/($G36-$F36),0) | S36: =IF(AND(12>$F36,12<=$G36),$E36/($G36-$F36),0) | T36: =IF(AND(13>$F36,13<=$G36),$E36/($G36-$F36),0) | U36: =IF(AND(14>$F36,14<=$G36),$E36/($G36-$F36),0) | V36: =IF(AND(15>$F36,15<=$G36),$E36/($G36-$F36),0) | W36: =IF(AND(16>$F36,16<=$G36),$E36/($G36-$F36),0)
A37: =WBS!A37 | B37: =WBS!B37 | C37: =WBS!D37 | D37: =WBS!E37 | E37: =WBS!J37 | F37: =CPM!E19 | G37: =CPM!F19 | H37: =IF(AND(1>$F37,1<=$G37),$E37/($G37-$F37),0) | I37: =IF(AND(2>$F37,2<=$G37),$E37/($G37-$F37),0) | J37: =IF(AND(3>$F37,3<=$G37),$E37/($G37-$F37),0) | K37: =IF(AND(4>$F37,4<=$G37),$E37/($G37-$F37),0) | L37: =IF(AND(5>$F37,5<=$G37),$E37/($G37-$F37),0) | M37: =IF(AND(6>$F37,6<=$G37),$E37/($G37-$F37),0) | N37: =IF(AND(7>$F37,7<=$G37),$E37/($G37-$F37),0) | O37: =IF(AND(8>$F37,8<=$G37),$E37/($G37-$F37),0) | P37: =IF(AND(9>$F37,9<=$G37),$E37/($G37-$F37),0) | Q37: =IF(AND(10>$F37,10<=$G37),$E37/($G37-$F37),0) | R37: =IF(AND(11>$F37,11<=$G37),$E37/($G37-$F37),0) | S37: =IF(AND(12>$F37,12<=$G37),$E37/($G37-$F37),0) | T37: =IF(AND(13>$F37,13<=$G37),$E37/($G37-$F37),0) | U37: =IF(AND(14>$F37,14<=$G37),$E37/($G37-$F37),0) | V37: =IF(AND(15>$F37,15<=$G37),$E37/($G37-$F37),0) | W37: =IF(AND(16>$F37,16<=$G37),$E37/($G37-$F37),0)
